Workbook

Sheet Existing Risk Grading
A1: COOPERATIVE BANK OF OROMIA S.C
A2: CREDIT RISK GRADING FOLRM EXISTING CUSTOMER AND BUSINESS
A3: 1. General Information
A4: a) Borrower's/Applicant's Name: | B4: XXX PLC | D4: MANUFACTURING | E4: Adopted grade by linked lending,if any, write below
A5: b) Group Name/Trade name,if any,
A6: c) Branch: | B6: XXXX
A7: d) Industry/Sector : | B7: DTS | C7: =IF(B7="MANUFACTURING",".",IF(B7="IMPORT/DTS",".",IF(B7="EXPORT",".",IF(B7="AGRICULTURE",".",IF(B7="CONSTRUCTION AND MACHINERY",".","")))))
A8: e) Customer's Classification: | B8: Business | C8: Business Line | D8: Manufacturing
A9: f) Current LAF No & Date: | C9: Loan Code
A10: g)Existing CBO Credit Facilities: | B10: Amount Approved | C10: Date Granted | D10: Balance as at 25/11/2022 | E10: Due Date
A11: DTS | B11: 70000000 | D11: 75465730 | E11: 28/03/2026
A12: Import overdraft | B12: 35000000 | D12: 26289759 | E12: 26/11/2022
A13: Revolving merchandise | B13: 40000000 | D13: 24818684 | E13: 44854
A14: Total | B14: =SUM(B11:B13) -> 145000000 | D14: =SUM(D11:D13) -> 1.2657417e+08
A15: h) Previous Risk Grade | E15: 2
A16: i) Current Risk Grade | E16: =IF(D68="incorrect","NG",IF(D18="incorrect","NG",IF(E68>0,E69,"Incorrect"))) -> 4
A17: 2.Risk Factors : Use the major business if existing businesses are >1, use the average of the last recent full years data. | C17: Maximum Achievable mark | D17: Customer's Actual Status (Interms of figure Word/Phrase) | E17: Achieved Score
A18: 2.1 Financial Risk : | C18: =SUM(C19:C27)% -> 0.35 | D18: =IF(E18>35,"INCORRECT",".") -> . | E18: =IF(D30="Y",(E19+E20+E21+E26+E27+E28+E29)*0.75,(E19+E20+E21+E26+E27+E28+E29)) -> 17
A19: A) Leverage=(Total Liability/Tangible Net Worth | B19: Manufacturing | C19: 8 | D19: =([1]Analysis!B71+[1]Analysis!C71+[1]Analysis!D71)/3 -> 0.71725935 | E19: =IF(B7="DTS","0",IF(B7="Import/Export","0",IF(D19<0.76,"8",IF(D19<=1.25,"5",IF(D19<=2,"3",IF(D19>2,"0","0")))))) -> 0
A20: B) Liquidity= (CA/CL) | B20: Manufacturing | C20: 8 | D20: =([1]Analysis!B69+[1]Analysis!C69+[1]Analysis!D69)/3 -> 1.2722892 | E20: =IF(B7="Agriculture","0",IF(B7="Construction","0",IF(B7="Import/Export","0",IF(D20>2.5,"8",IF(D20>=1.75,"7",IF(D20>=1,"5",IF(D20>=0.5,"3",IF(D20>=0.01,"0","8")))))))) -> 5
A21: C)Profitability= (OP/Sales x 100 | B21: Manufacturing | C21: 7 | D21: =[1]Analysis!F81 -> 0.059070991 | E21: =IF(B7="Construction","0",IF(B7="DTS","0",IF(B7="Import/Export","0",IF(D21>=5,"7",IF(D21>=4,"6",IF(D21>=3,"5",IF(D21>=2,"3",IF(D21<2,"1","0")))))))) -> 0
A26: D)Debt Service Coverage: (Profit before interest & tax / Interest Exp) | B26: Manufacturing | C26: 6 | D26: =[1]Analysis!F82 -> 0.91484983 | E26: =IF(B7="Construction","0",IF(B7="Import/Export","0",IF(D26="NA","0",IF(D26>2.5,"6",IF(D26>=2,"5",IF(D26>=1.5,"4",IF(D26>=1,"3",IF(D26<1,"0")))))))) -> 0
A27: E)Qualityof Financial Statements: ….. | B27: All Sectors >=Br. 1 Million Exposure | C27: 6 | D27: EX | E27: =IF(D27="EX","6",IF(D27="VG","5",IF(D27="GD","4",IF(D27="FR","3",IF(D27="CCR","0",IF(D27="NA","0","0")))))) -> 6
B28: All Sectors Below Br.1 Million Exposure | D28: EX | E28: =IF(D28="EX","6",IF(D28="VG","5",IF(D28="CCR","3",IF(D28="NA","0","0")))) -> 6
B29: Descrepancies:(Mj or Mn) | D29: NA | E29: =IF(D29="Mj","-5",IF(D29="Mn","-2",IF(D29="NA","0","0"))) -> 0
B30: Is the last F.Statement CCR ? | D30: YES
A31: 3. Business/Industry Risk: | C31: =(C32+C33)/100 -> 0.1 | E31: =E32+E33 -> 7
A32: a) Business outlook(Cyclicality) & Growth | C32: 6 | D32: STABLE | E32: =IF(D32="Favourable","6",IF(D32="Stable","5",IF(D32="Unstable","2",IF(D32="NA","0","0")))) -> 5
A33: b) Market competition/Market share | C33: 4 | D33: AVERAGE | E33: =IF(D33="Dominant","4",IF(D33="Average","2",IF(D33="Weak","0",IF(D33="NA","0","0")))) -> 2
A34: 4. Management Risk | C34: =(C35+C36+C37)/100 -> 0.15 | E34: =E35+E36+E37 -> 10
A35: a) Experience in Related Line of Business | C35: 8 | D35: EX | E35: =IF(D35="NA","0",IF(D35="EX","8",IF(D35="VG","7",IF(D35="GD","6",IF(D35="WK","2","0"))))) -> 8
A36: b) Qualification | C36: 5 | D36: GD | E36: =IF(D36="NA","0",IF(D36="EX","5",IF(D36="VG","4",IF(D36="GD","2",IF(D36="WK","0","0"))))) -> 2
A37: c) Sucession Plan | C37: 2 | D37: NO | E37: =IF(D37="NA","0",IF(D37="Ready","2",IF(D37="No","0","0"))) -> 0
A38: 5.Account Performance Average Score | C38: =(C39+C43+C49)/3 -> 0.25 | D38: =IF(E38>25,"INCORRECT",".") -> . | E38: =(E39+E43+E46+E49+E52+E55+E57+E60)/E63+(E62) -> 7.125
A39: 5.1) Overdraft | C39: =(C40+C41+C42)/100 -> 0.25 | E39: =E40+E41+E42 -> 21
B40: i) Highest Debit | C40: 7 | D40: =(99%+99%+99%)/3 -> 0.99 | E40: =IF(D40<0.01,"0",IF(D40<60%,"3",IF(D40>=85%,"7",IF(D40>=60%,"5",0)))) -> 7
B41: ii) Lowest balance | C41: 8 | D41: GD | E41: =IF(D41="NA","0",IF(D41="EX","8",IF(D41="VG","6",IF(D41="GD","4","0")))) -> 4
B42: iii) Turnover | C42: 10 | D42: GD | E42: =IF(D42="NA","0",IF(D42>3,"10",IF(D42>=2,"7",IF(D42>=1,"4",IF(D42<1,0))))) -> 10
A43: 5.2)Term Loan | C43: =(C44+C45)/100 -> 0.25 | E43: =E44+E45 -> 12
B44: i) Current Loan Repayment status | C44: 15 | D44: GD | E44: =IF(D44="NA","0",IF(D44="EX","15",IF(D44="VG","10",IF(D44="GD","5",IF(D44="WK","0","0"))))) -> 5
...

Sheet Financial 40
B2: Risk Aspects | C2: Sector | I2: Source of Data | J2: Responsible Organ to provide data
C3: Manufacturing | D3: Agriculture | E3: Import & DTS | F3: Export | G3: Construction & Machinery | H3: Score
B4: Financial Position (40%) | J4: Customer
B5: Leverage (Total liability to total asset) 6% | C5: ≤50% | D5: ≤50% | E5: ≤60% | F5: ≤70% | G5: ≤50% | H5: 0.06 | I5: Financial Statements
C6: 70%-50% | D6: 70%-50% | E6: 70%-60% | F6: 85%-70% | G6: 70%-50% | H6: 0.04
C7: 90%-70% | D7: 90%-70% | E7: 90% -70% | F7: 95%-85% | G7: 90%-70% | H7: 0.02
C8: >90% | D8: >90% | E8: >90% | F8: >95% | G8: >90% | H8: 0
B9: Liquidity (Current Ratio = CA/CL) 5% | C9: > 2 | D9: >2 | E9: > 1.5 | F9: > 1.25 | G9: > 2 | H9: 0.05
C10: 1.5 - 2.0 | D10: 1.5 - 2 | E10: 1.0 - 1.5 | F10: 1.0- 1.25 | G10: 1.5 -2 | H10: 0.04
C11: 1-1.5 | D11: 1.25 - 1.5 | E11: 0.75 - 1.5 | F11: 0.75 -1.0 | G11: 1-1.5 | H11: 0.03
C12: 0.5-1 | D12: 0.75-1.25 | E12: 0.5 - 0.75 | F12: 0.5- 0.75 | G12: 0.5 – 1.0 | H12: 0.02
C13: < 0.5 | D13: < 0.75 | E13: < 0.5 | F13: < 0.5 | G13: < 0.5 | H13: 0
B14: Profitability
B15: Return on Asset =Net Income after tax /Total asset) 3% | C15: ≥10% | D15: ≥15% | E15: ≥ 15% | F15: ≥ 15% | G15: ≥ 19% | H15: 0.03 | I15: =I5 -> Financial Statements
C16: 8% -10% | D16: 10%-15% | E16: 10%- 15% | F16: 10%-15% | G16: 16% -19% | H16: 0.025
C17: 6%-8% | D17: 7% -10% | E17: 8% -10% | F17: 8% -10% | G17: 11% -16% | H17: 0.02
C18: 3%-6% | D18: 3%-7% | E18: 4%-8% | F18: 4%-8% | G18: 6% - 11% | H18: 0.01
C19: 1%- 3% | D19: 1%- 3% | E19: 1%- 4% | F19: 1%- 4% | G19: 1%- 6% | H19: 0.005
C20: < 1% | D20: <1% | E20: < 1% | F20: < 1% | G20: < 1% | H20: 0
B21: Operating profit Margin(Operating profit/Total Sales) 5% | C21: ≥20% | D21: ≥22% | E21: ≥20% | F21: ≥ 23% | G21: ≥ 20% | H21: 0.05
C22: 15% - 20% | D22: 16%-22% | E22: 15% -20% | F22: 16%-22% | G22: 15% -20% | H22: 0.04
C23: 10% -15% | D23: 11%-16% | E23: 10%-15% | F23: 11%-16% | G23: 10% -15% | H23: 0.03
C24: 5% -10% | D24: 6% -11% | E24: 5% -10% | F24: 6% -11% | G24: 5% -10% | H24: 0.02
C25: < 5% | D25: < 6% | E25: < 5% | F25: < 6% | G25: < 5% | H25: 0.01
B26: Debt Service Coverage Ratio (Net income after tax/Interest expenses) 3% | C26: > 2.5 | D26: > 2.5 | E26: > 2.5 | F26: > 3 | G26: > 2 | H26: 0.03
C27: 2-2.5 | D27: 1.5 - 2.5 | E27: 2-2.5 | F27: .2-3 | G27: 1.5-2 | H27: 0.025
C28: 1.5-2 | D28: 1-1.5 | E28: 1.5-2 | F28: .1-2 | G28: 1 -1.5 | H28: 0.02
C29: 1-1.5 | D29: 0.5-1 | E29: 1-1.5 | F29: 0.5-1 | G29: 0.5 -1 | H29: 0.01
C30: < 1 | D30: < 0.5 | E30: < 1 | F30: < 0.5 | G30: < 0.5 | H30: 0
B31: Inventory Turnover Ratio (CGS/Average Inventory) 4% | C31: >12 | D31: >3 | E31: >8 | F31: >4 | G31: >10 | H31: 0.04
C32: 8-12 | D32: 2-3 | E32: 4-8 | F32: 2-4 | G32: 7-10 | H32: 0.03
C33: 4-8 | D33: 1-2 | E33: 2-4 | F33: 1-2 | G33: 3-7 | H33: 0.02
C34: <4 | D34: <1 | E34: <2 | F34: <1 | G34: <3 | H34: 0.01
B35: Return on Equity (Net Income / Equity) 4% | C35: >15% | H35: 0.04
C36: 12%-15% | H36: 0.03
C37: 10%-12% | H37: 0.02
C38: 5%-10% | H38: 0.01
C39: <5% | H39: 0
B40: Quality of Financial Statement 5%
B41: Quality of Financial Statement 5% | C41: All Audited up to date | H41: 0.05 | I41: =I15 -> Financial Statements
...

Sheet Industry attractiveness 10
C2: Industry attractiveness
C3: Measurement | D3: Parameters | E3: Score | F3: ='Financial 40'!I2 -> Source of Data | G3: Responsible Organ
B4: Business/Industry and form of organization Risk (10%) | C4: Business/Industry outlook of the customer | D4: Favorable | E4: 0.04 | F4: Credit Appraisal Assessment | G4: Credit Analysts
D5: Stable | E5: 0.02
D6: Unstable | E6: 0
C7: Market competition/market | D7: Dominant player | E7: 0.03
D8: Acceptable | E8: 0.02
D9: Weak Player | E9: 0
C10: Form of Organization | D10: Cooperatives | E10: 0.03
D11: Share Company | E11: 0.02
D12: Private limited company | E12: 0.02
D13: Sole proprietorship | E13: 0.01
E14: =E4+E7+E10 -> 0.1

Sheet Credit History 25
B1: S/N | C1: Measurement | D1: Parameters | F1: Score | G1: ='Industry attractiveness 10'!F3 -> Source of Data | H1: ='Industry attractiveness 10'!G3 -> Responsible Organ
B2: Credit History 25%
B3: 1 | C3: Overdraft Facility (21%)
C4: Swing | G4: Loan statements | H4: =H28 -> Can be generated from CBS
C5: Highest debit 6% | D5: ≥ 85%/ year | F5: 0.06
D6: 60% - 84.9%/ year | F6: 0.05
D7: < 60%/year | F7: 0.03 | I7: requirest claificcation
C8: Lowest debit 7% | D8: At least credit balance within three months | F8: 0.07
D9: At least a credit balance within six months | F9: 0.06
D10: At least a credit balance within a year | F10: 0.05
D11: At least 4% debit balance within a year | F11: 0.03
D12: Greater than 4% debit balance within a year | F12: 0
C13: Turnover 8% | D13: X >= 4 times of the limit | F13: 0.08
D14: 2.5≤X<4 | F14: 0.07
D15: 1≤X<2.5 | F15: 0.04
D16: X < 1 | F16: 0
B17: 2 | C17: T/Loan Performance (21%) | G17: CIC | H17: CIC Team
C18: Existing loan repayment 13% | D18: Regular repayment | F18: 0.13
D19: 1 - 30 days in arrears | F19: 0.1
D20: 31-90 days in arrears | F20: 0.05
D21: More than 90 days in arrears | F21: 0
C22: Settled loans 8% | D22: Settled with regular repayment | F22: 0.08 | I22: calcification/CBS team
D23: Settled timely but with an element of irregularity | F23: 0.07
D24: Settled before sixty days after due date | F24: 0.05
D25: Settled after 60 days but less than ninety days | F25: 0.03
D26: Settled after being NPL and/ or through foreclosure, legal action | F26: 0
B27: 3 | C27: L/C Facility (21%)
C28: Average settlement of import L/C facility (21%) | D28: Settled within a month | F28: 0.21 | G28: =G4 -> Loan statements | H28: Can be generated from CBS
D29: Settled within two months | F29: 0.15 | I29: calcification/CBS team, credit team, trade service
D30: Settled within three months | F30: 0.05
D31: Settled after three months | F31: 0
B32: 4 | C32: Merchandise Loan Limit - 21% | G32: =G28 -> Loan statements | H32: =H28 -> Can be generated from CBS
C33: Settlement of Merchandise Loan 13% | D33: Settled all advances within due date | F33: 0.13
D34: Settled within 30 days from the due date | F34: 0.1
D35: Settled within 45 days from the due date, | F35: 0.05
D36: Settled after 45 days from the due date | F36: 0
C37: Turn-over (8%) | D37: >3 times | F37: 0.08
D38: 2-3 times | F38: 0.07
D39: 1.25- 1.9 times | F39: 0.06
D40: 0.5-1.24 times | F40: 0.04
...

Sheet Banking Relationship 9
B3: Banking Relationship (10%) | E3: ='Credit History 25'!G1 -> Source of Data
B4: Measurement | C4: Parameters | D4: Score
B5: Length of relationship with CBO (4%) | C5: > 3years | D5: 0.04 | E5: CBS
C6: 2 - 3 years | D6: 0.02
C7: 1 – 2 years | D7: 0.01
C8: < 1 year | D8: 0.005
B9: The account transaction to sales percentage share with CBO(6%) | C9: >100% | D9: 0.06 | E9: CBS
C10: 90-99.9% | D10: 0.05
C11: 80-89.9% | D11: 0.04
C12: 70-79.9% | D12: 0.03 | F12: coop stream work flow
C13: 60-69.9% | D13: 0.02
C14: 50-59.9% | D14: 0.01
C15: <50% | D15: 0
D16: =D9+D5 -> 0.1

Sheet Integrity 6
B3: Character of applicant/management (6%) | E3: ='Banking Relationship 9'!E3 -> Source of Data | F3: ='Credit History 25'!H1 -> Responsible Organ
B4: Measurement | C4: Parameters | D4: Score | E4: ='Industry attractiveness 10'!F4:F13 -> Credit Appraisal Assessment | F4: ='Industry attractiveness 10'!G4:G13 -> Credit Analysts
B5: Consistency of presented document (2%) | C5: Adequate | D5: 0.02 | G5: yes
C6: Acceptable | D6: 0.01
C7: Inconsistent | D7: 0
B8: Responsiveness to wards bank's inquiry (2%) | C8: Provides consistently prompt | D8: 0.02
C9: Response and willingly | D9: 0.015 | G9: yes
C10: Responds with repeated Inquiry | D10: 0.01
C11: Not responsive or willing | D11: 0
B12: Corporate Responsibility (Tax Payment) (2%) | C12: Perfect | D12: 0.02 | G12: yes
C13: Acceptable | D13: 0.01
C14: Inconsistent | D14: 0
D15: =D5+D8+D12 -> 0.06

Sheet Management Capacity  9
B3: Management and Ownership Risk (9%) | F3: ='Integrity 6'!E3 -> Source of Data | G3: ='Integrity 6'!F3 -> Responsible Organ
B4: S/No | C4: Measurement | D4: Parameters | E4: Score | G4: Source not available (CRM)
B5: 1 | C5: Experience in related Line of Business (4%) | D5: >10 | E5: 0.04 | F5: DDR
D6: 7- 10 years | E6: 0.03
D7: 3- 7 Years | E7: 0.02
D8: < 3 years | E8: 0.01
B9: 2 | C9: Qualification (3%) | D9: If 51% and above of the top management Members are 1st Degree and above graduates | E9: 0.03 | F9: =F5 -> DDR
D10: If 51% and above of the top management Members are Diplomaand above graduates | E10: 0.02
D11: If 51% and above of the top management members are High School and above graduates | E11: 0.01
D12: If 51% and above of the top management members are below High School graduates | E12: 0
B13: 3 | C13: Availability of clear duty and Segregation (2%) | D13: Clear outlined duties and responsibility supported by organizational structure | E13: 0.02 | F13: =F9 -> DDR
D14: Semi segregated duties and responsibilities supported by organizational structure | E14: 0.01
D15: Unclear duties, responsibilities and control system breached | E15: 0
E16: =E13+E9+E5 -> 0.09

Sheet Business Risk  Summary
B3: Range of Achievement | C3: Grade | D3: Risk level | E3: Bankability
B4: 95% - 100% | C4: I | D4: Exceptionally low Risk | E4: Prime (Prominent)(bankable)
B5: 80% - 94.9% | C5: II | D5: Very Low Risk | E5: Reputable (Bankable)
B6: 65% - 79.9% | C6: III | D6: Low Risk | E6: Acceptable(Bankable)
B7: 50% - 64.9% | C7: IV | D7: Moderate risk | E7: Watch list (Bankable)
B8: < 50% | C8: V | D8: High risk | E8: Doubtful(Un-bankable )

Sheet Security Related Factor
B3: Collateral Risk (100%)
B4: Collateral Type (20%) | C4: Type of collateral | D4: Score
C5: Cash, Cash Substitutes | D5: 0.2
C6: Building, Share certificate, Merchandize | D6: 0.18
C7: Machinery , Vehicle | D7: 0.16
C8: Corporate/Government/Bank and Personal Guarantee | D8: 0.12
C9: Export Document | D9: 0.14
C10: Land Lease Right/Coffee Plantation | D10: 0.12
C11: Second Degree Mortgage | D11: 0.1
B12: Collateral to Loan Coverage Ratio (80%) | C12: >110% | D12: 0.8
C13: 100%-110% | D13: 0.75
C14: 80%-99.9% | D14: 0.7
C15: 60%-79.9% | D15: 0.6
C16: 50%-59.9% | D16: 0.5
C17: 40%-49.9% | D17: 0.4
C18: 30%-39.9% | D18: 0.3
C19: X<30% | D19: 0
B24: Collateral Risk For Cooperatives (100%)
B25: Collateral Type (20%) | C25: Type of collateral | D25: Score
C26: Cash, Cash Substitutes | D26: 0.2
C27: Building, Share certificate, Merchandize | D27: 0.18
C28: Machinery , Vehicle | D28: 0.16
C29: Corporate/Government/Bank and Personal Guarantee | D29: 0.12
C30: Export Document | D30: 0.14
C31: Land Lease Right/Coffee Plantation | D31: 0.12
C32: Second Degree Mortgage | D32: 0.1
B33: Collateral to Loan Coverage Ratio (80%) | C33: >60% | D33: 0.8
C34: 50%-60% | D34: 0.7
C35: 40%-49.9% | D35: 0.6
C36: 30%-39.9% | D36: 0.5
C37: 20%-29.9% | D37: 0.4
C38: 10%-19.9% | D38: 0.3
C39: X<10% | D39: 0
B40: In addition , the pricing will be different(lower) from other customers

Sheet Coll Summary
B2: Description | C2: Value | D2: Grade | E2: Risk Level
B3: Strongly Secured | C3: 90% - 100% | D3: A | E3: No risk
B4: Fully Secured | C4: 80% - 89.9% | D4: B | E4: Low risk
B5: Partially Secured | C5: 70% - 79.9% | D5: C | E5: Moderate risk
B6: Partially Secured | C6: 50% - 69.9% | D6: D | E6: High risk
B7: Unsecured | C7: < 50% | D7: E | E7: Very high risk
B14: Security Strength \ Borrower Business Strength | C14: Borrower Business Strength
A15: Security Strength | C15: Prime | D15: Acceptable | E15: Watch list | F15: Doubtful | G15: Loss
B16: Strongly Secured | C16: AAA | D16: AA | E16: A | F16: BBB | G16: BB
B17: Fully Secured | C17: AA | D17: A | E17: BBB | F17: BB | G17: CCC
B18: Partially Secured with moderate risk | C18: A | D18: BBB | E18: BB | F18: CCC | G18: CC
B19: Partially Secured with high risk | C19: BBB | D19: BB | E19: CCC | F19: CC | G19: C
B20: Unsecured | C20: BB | D20: CCC | E20: CC | F20: C | G20: D

Sheet Interpretation
B2: Bankability | C2: Collateral coverage and Risk level | D2: Risk matrix | E2: Risk Grade
B3: Prime (Prominent) (bankable) | C3: Strongly Secured with Exceptionally low Risk | D3: I &A,I & B and II & A | E3: 1
B4: Reputable (Bankable) | C4: Fully Secured with Very Low Risk | D4: I & C,II & B and III & A | E4: 2
B5: Acceptable(Bankable) | C5: Partially secured with Low Risk | D5: I & D, I & E, II &C, II & D, II & E, III & B, III & C and IV & A | E5: 3
B6: Watch list (Bankable) | C6: Partially Secured with Moderate risk | D6: III & D, III & E, IV&B and IV&C | E6: 4
B7: Doubtful(Un-bankable ) | C7: Unsecured with High risk | D7: IV & D, IV & E,V & A-E | E7: 5
C10: Collateral RISK
B11: Bankability | D11: A | E11: B | F11: C | G11: D | H11: E
C12: I | D12: 1 | E12: 1 | F12: 2 | G12: 3 | H12: 3
C13: II | D13: 1 | E13: 2 | F13: 3 | G13: 3 | H13: 3
C14: III | D14: 2 | E14: 3 | F14: 3 | G14: 4 | H14: 4
C15: IV | D15: 3 | E15: 4 | F15: 4 | G15: 5 | H15: 5
C16: V | D16: 5 | E16: 5 | F16: 5 | G16: 5 | H16: 5
