Workbook
Name Beg_Bal: #REF!
Name Cum_Int: #REF!
Name Data: #REF!
Name End_Bal: #REF!
Name Extra_Pay: #REF!
Name Full_Print: #REF!
Name Header_Row: ROW(#REF!)
Name Int: #REF!
Name Interest_Rate: #REF!
Name Last_Row: IF([0]!Values_Entered,Header_Row+[0]!Number_of_Payments,Header_Row)
Name Loan_Amount: #REF!
Name Loan_Start: #REF!
Name Loan_Years: #REF!
Name Num_Pmt_Per_Year: #REF!
Name Number_of_Payments: MATCH(0.01,End_Bal,-1)+1
Name Pay_Date: #REF!
Name Pay_Num: #REF!
Name Payment_Date: DATE(YEAR(Loan_Start),MONTH(Loan_Start)+Payment_Number,DAY(Loan_Start))
Name Princ: #REF!
Name Print_Area_Reset: OFFSET(Full_Print,0,0,Last_Row)
Name Sched_Pay: #REF!
Name Scheduled_Extra_Payments: #REF!
Name Scheduled_Interest_Rate: #REF!
Name Scheduled_Monthly_Payment: #REF!
Name Total_Interest: #REF!
Name Total_Pay: #REF!
Name Values_Entered: IF(Loan_Amount*Interest_Rate*Loan_Years*Loan_Start>0,1,0)
Name zAutoHide4_0335: #REF!

Sheet Merchandise Turnover
B1: Cooperative Bank of Oromia
B4: Customer Name:
B5: Type of Facility
B6: Industry Type
B7: Account Number
B8: Approved Amount
B9: Date Approved
B10: Reporting Date
B13: Month | C13: Debit (Disbursements) | D13: Credit (Principal Repayments)
B26: Total | C26: =SUM(C14:C25) -> 0 | D26: =SUM(D14:D25) -> 0
C28: Prepared by | D28: _____________________

Sheet Pre-Shipment Turnover
B1: Cooperative Bank of Oromia
B4: Customer Name:
B5: Type of Facility
B6: Industry Type
B7: Account Number
B8: Approved Amount
B9: Date Approved
B10: Reporting Date
B13: Month | C13: Debit (Disbursements) | D13: Credit (Principal Repayments)
B26: Total | C26: =SUM(C14:C25) -> 0 | D26: =SUM(D14:D25) -> 0
C28: Prepared by | D28: _____________________

Sheet OD TURNOVER
A2: Turnover Analysis
A3: Account Holder:
A4: Account Number
A5: Industry
A6: Sanction Limit
A7: Approved Date
A8: Facility Type
A9: Report Date:
A10: Status
A12: MONTH | B12: TOTAL TURNOVER CREDIT | C12: TOTAL TURNOVER DEBIT | D12: NUMBER OF CREDIT ENTRY | E12: MONTHELY CREDIT AVG | F12: UTILIZATION PERCENTAGE
B27: Prepared by | C27: _____________________

Sheet OD SWING
A2: Swing Analysis
A3: Account Holder:
A4: Account Number
A5: Industry
A6: Sanction Limit
A7: Approved Date
A8: Facility Type
A9: Report Date:
A10: Status
A12: MONTH | B12: HIGHEST UTILIZATION | C12: DATE HIGH | D12: LOWEST UTILIZATION | E12: DATE LOW | F12: UTILIZATION %
F13: HIGH | G13: LOW
B28: Prepared by | C28: _____________________

Sheet Account Statement
A2: Turnover Analysis
A3: Account Holder:
A4: Account Number
A5: Industry
A6: Sanction Limit
A7: Approved Date
A8: Facility Type
A9: Date Account Opened
A10: Report Date:
A11: Status
A13: MONTH | B13: TOTAL TURNOVER CREDIT | C13: TOTAL TURNOVER DEBIT | D13: NUMBER OF CREDIT ENTRY | E13: MONTHLY CREDIT AVG | F13: UTILIZATION PERCENTAGE
B28: Prepared by | C28: _____________________

Sheet Financial Statement
A1: ABC Company
A2: Balance Sheet as at…
A3: Description | B3: July 07, 2025 G.C | C3: July 7, 2024 G.C | D3: July 7, 2023 G.C | E3: July 7, 2022 G.C | F3: Average
B4: (Audited) | C4: (Audited) | D4: (Audited) | E4: (Audited)
A5: Assets
A6: Non-current assets
A7: Property, plant & equipment | F7: =AVERAGE(B7:E7) -> #DIV/0!
A8: Total Non-current Assets | B8: =SUM(B7) -> 0 | C8: =SUM(C7) -> 0 | D8: =SUM(D7) -> 0 | E8: =SUM(E7) -> 0 | F8: =AVERAGE(B8:E8) -> 0
A9: Current Assets
A10: Stocks | F10: =AVERAGE(B10:E10) -> #DIV/0!
A11: Trade and other receivables | F11: =AVERAGE(B11:E11) -> #DIV/0!
A12: Cash on hand and at bank | F12: =AVERAGE(B12:E12) -> #DIV/0!
A13: Total Current Assets | B13: =SUM(B10:B12) -> 0 | C13: =SUM(C10:C12) -> 0 | D13: =SUM(D10:D12) -> 0 | E13: =SUM(E10:E12) -> 0 | F13: =AVERAGE(B13:E13) -> 0
A14: Total Assets | B14: =B13+B8 -> 0 | C14: =C13+C8 -> 0 | D14: =D13+D8 -> 0 | E14: =E13+E8 -> 0 | F14: =AVERAGE(B14:E14) -> 0
A15: Liabilities
A16: Current Liabilities
A17: Trade & other payables | F17: =AVERAGE(B17:E17) -> #DIV/0!
A18: Other Payables | F18: =AVERAGE(B18:E18) -> #DIV/0!
A19: Shareholder account | F19: =AVERAGE(B19:E19) -> #DIV/0!
A20: Profit tax payable | F20: =AVERAGE(B20:E20) -> #DIV/0!
A21: Total current liability | B21: =SUM(B17:B20) -> 0 | C21: =SUM(C17:C20) -> 0 | D21: =SUM(D17:D20) -> 0 | E21: =SUM(E17:E20) -> 0 | F21: =SUM(F17:F20) -> #DIV/0!
A22: Long term liabilities | B22: =SUM(B23:B24) -> 0 | C22: =SUM(C23:C24) -> 0 | D22: =SUM(D23:D24) -> 0 | E22: =SUM(E23:E24) -> 0 | F22: =SUM(F18:F21) -> #DIV/0!
A23: Bank Loan | F23: =SUM(F19:F22) -> #DIV/0!
A24: Lease payable
A25: Total liabilities | B25: =B21+B22 -> 0 | C25: =C21+C22 -> 0 | D25: =D21+D22 -> 0 | E25: =E21+E22 -> 0 | F25: =F21+F22 -> #DIV/0!
A26: Capital
A27: Capital | F27: =AVERAGE(B27:E27) -> #DIV/0!
A28: Reserve | F28: =AVERAGE(B28:E28) -> #DIV/0!
A29: Retained Earning | F29: =AVERAGE(B29:E29) -> #DIV/0!
A30: Total Capital | B30: =SUM(B27:B29) -> 0 | C30: =SUM(C27:C29) -> 0 | D30: =SUM(D27:D29) -> 0 | E30: =SUM(E27:E29) -> 0 | F30: =SUM(F27:F29) -> #DIV/0!
A31: Total Liability & Capital | B31: =B30+B25 -> 0 | C31: =C30+C25 -> 0 | D31: =D30+D25 -> 0 | E31: =E30+E25 -> 0 | F31: =F30+F25 -> #DIV/0!
A32: Net Working Capital | B32: =B13-B21 -> 0 | C32: =C13-C21 -> 0 | D32: =D13-D21 -> 0 | E32: =E13-E21 -> 0 | F32: =AVERAGE(B32:E32) -> 0
A33: Tangible Net Worth | B33: =B14-B25 -> 0 | C33: =C14-C25 -> 0 | D33: =D14-D25 -> 0 | E33: =E14-E25 -> 0 | F33: =F14-F25 -> #DIV/0!
B34: =B14-B31 -> 0 | C34: =C14-C31 -> 0 | D34: =D14-D31 -> 0 | E34: =E14-E31 -> 0
A36: =A1 -> ABC Company
A37: Income Statement as at …
A38: Description | B38: =B3 -> July 07, 2025 G.C | C38: =C3 -> July 7, 2024 G.C | D38: =D3 -> July 7, 2023 G.C | E38: =E3 -> July 7, 2022 G.C | F38: =F3 -> Average
B39: =B4 -> (Audited) | C39: =C4 -> (Audited) | D39: =D4 -> (Audited) | E39: =E4 -> (Audited)
A40: Sales | F40: =AVERAGE(B40:E40) -> #DIV/0!
A41: Less: Cost of Goods Sold | F41: =AVERAGE(B41:E41) -> #DIV/0!
...

Sheet Credit Information
B1: Credit Information
C2: Current Exposure with CoopBank
B3: Sr. No | C3: Existing Exposure with CoopBank | D3: Lending Bank | E3: Date Granted | F3: Expiry Date | G3: Credit Product | H3: Amount Granted | I3: Total Current Balance | J3: Status
B4: 1 | C4: Revolving Facility
B14: Total | H14: =SUM(H4:H13) -> 0 | I14: =SUM(I4:I13) -> 0
B15: 2 | C15: Non-Revolving loan
B26: Total | H26: =SUM(H15:H25) -> 0 | I26: =SUM(I15:I25) -> 0
B27: Grand Total Credit | H27: =H26+H14 -> 0 | I27: =I26+I14 -> 0
C29: Current Exposure with Other Bank
B30: Sr. No | C30: Existing Exposure with Other Bank | D30: Lending Bank | E30: Date Granted | F30: Expiry Date | G30: Credit Product | H30: =H3 -> Amount Granted | I30: Total Current Balance | J30: Status
B31: 1 | C31: Revolving Facility
B49: Sub Total | H49: =SUM(H31:H48) -> 0 | I49: =SUM(I31:I48) -> 0
B50: 2 | C50: Non-Revolving loan
B76: Sub Total | H76: =SUM(H50:H75) -> 0 | I76: =SUM(I50:I75) -> 0
B77: Grand Total | H77: =H76+H49 -> 0 | I77: =I76+I49 -> 0
J78: {=IF(OR(J31:J77="Substandard",J31:J77="Doubtful",J31:J77="Loss"),"NPL","")}
C80: Prepared by | D80: _____________________

Sheet Collateral
A3: No | B3: Type of collateral | C3: Year of Manufacturing | D3: Age | E3: Value | F3: Valuation Method | G3: Mandatory Method | H3: Discount Rate | I3: Net Value
A4: 1 | J4: =B4 -> 0
A5: 2 | D5: =YEAR(TODAY())-C5 -> 2026 | G5: =IF(OR(B5='Security Related Factor'!$D$10,B5='Security Related Factor'!$D$11),IF(AND(D5>3,F5="Invoice"),0,1)) -> FALSE | H5: =IF(AND(B5<>'Security Related Factor'!$D$10,B5<>'Security Related Factor'!$D$11,B5<>'Security Related Factor'!$D$15,B5<>'Security Related Factor'!$D$16,B5<>'Security Related Factor'!$D$19),100%, IF(OR(B5='Security Related Factor'!$D$15,B5='Security Related Factor'!$D$16,B5='Security Related Factor'!$D$19),0%, IF(OR(B5='Security Related Factor'!$D$10,B5='Security Related Factor'!$D$11),IF(AND(D5<=1,F5="Invoice"),90%*G5, IF(OR(B5='Security Related Factor'!$D$10,B5='Security Related Factor'!$D$11),IF(AND(D5>1,D5<=3,F5="Invoice"),80%*G5, IF(OR(B5='Security Related Factor'!$D$10,B5='Security Related Factor'!$D$11),IF(AND(D5>4,F5="Invoice"),0%*G5, IF(OR(B5='Security Related Factor'!$D$10,B5='Security Related Factor'!$D$11),IF(AND(D5<=1,F5="Insurance"),80%*G5, IF(OR(B5='Security Related Factor'!$D$10,B5='Security Related Factor'!$D$11),IF(AND(D5>1,D5<=3,F5="Insurance"),70%*G5, IF(OR(B5='Security Related Factor'!$D$10,B5='Security Related Factor'!$D$11),IF(AND(D5>3,D5<=5,F5="Insurance"),60%*G5, IF(OR(B5='Security Related Factor'!$D$10,B5='Security Related Factor'!$D$11),IF(AND(D5>5,D5<=7,F5="Insurance"),50%*G5, IF(OR(B5='Security Related Factor'!$D$10,B5='Security Related Factor'!$D$11),IF(AND(D5>7,D5<=10,F5="Insurance"),40%*G5, IF(OR(B5='Security Related Factor'!$D$10,B5='Security Related Factor'!$D$11),IF(AND(D5>10,D5<=15,F5="Insurance"),25%*G5, IF(OR(B5='Security Related Factor'!$D$10,B5='Security Related Factor'!$D$11),IF(AND(D5>15,F5="Insurance"),0%*G5)))))))))))))))))))))) -> 1 | I5: =IF(B5="","",H5*E5) | J5: =B5 -> 0
A6: 3 | D6: =YEAR(TODAY())-C6 -> 2026 | G6: =IF(OR(B6='Security Related Factor'!$D$10,B6='Security Related Factor'!$D$11),IF(AND(D6>3,F6="Invoice"),0,1)) -> FALSE | H6: =IF(AND(B6<>'Security Related Factor'!$D$10,B6<>'Security Related Factor'!$D$11,B6<>'Security Related Factor'!$D$15,B6<>'Security Related Factor'!$D$16,B6<>'Security Related Factor'!$D$19),100%, IF(OR(B6='Security Related Factor'!$D$15,B6='Security Related Factor'!$D$16,B6='Security Related Factor'!$D$19),0%, IF(OR(B6='Security Related Factor'!$D$10,B6='Security Related Factor'!$D$11),IF(AND(D6<=1,F6="Invoice"),90%*G6, IF(OR(B6='Security Related Factor'!$D$10,B6='Security Related Factor'!$D$11),IF(AND(D6>1,D6<=3,F6="Invoice"),80%*G6, IF(OR(B6='Security Related Factor'!$D$10,B6='Security Related Factor'!$D$11),IF(AND(D6>4,F6="Invoice"),0%*G6, IF(OR(B6='Security Related Factor'!$D$10,B6='Security Related Factor'!$D$11),IF(AND(D6<=1,F6="Insurance"),80%*G6, IF(OR(B6='Security Related Factor'!$D$10,B6='Security Related Factor'!$D$11),IF(AND(D6>1,D6<=3,F6="Insurance"),70%*G6, IF(OR(B6='Security Related Factor'!$D$10,B6='Security Related Factor'!$D$11),IF(AND(D6>3,D6<=5,F6="Insurance"),60%*G6, IF(OR(B6='Security Related Factor'!$D$10,B6='Security Related Factor'!$D$11),IF(AND(D6>5,D6<=7,F6="Insurance"),50%*G6, IF(OR(B6='Security Related Factor'!$D$10,B6='Security Related Factor'!$D$11),IF(AND(D6>7,D6<=10,F6="Insurance"),40%*G6, IF(OR(B6='Security Related Factor'!$D$10,B6='Security Related Factor'!$D$11),IF(AND(D6>10,D6<=15,F6="Insurance"),25%*G6, IF(OR(B6='Security Related Factor'!$D$10,B6='Security Related Factor'!$D$11),IF(AND(D6>15,F6="Insurance"),0%*G6)))))))))))))))))))))) -> 1 | I6: =IF(B6="","",H6*E6) | J6: =B6 -> 0
A7: 4 | D7: =YEAR(TODAY())-C7 -> 2026 | G7: =IF(OR(B7='Security Related Factor'!$D$10,B7='Security Related Factor'!$D$11),IF(AND(D7>3,F7="Invoice"),0,1)) -> FALSE | H7: =IF(AND(B7<>'Security Related Factor'!$D$10,B7<>'Security Related Factor'!$D$11,B7<>'Security Related Factor'!$D$15,B7<>'Security Related Factor'!$D$16,B7<>'Security Related Factor'!$D$19),100%, IF(OR(B7='Security Related Factor'!$D$15,B7='Security Related Factor'!$D$16,B7='Security Related Factor'!$D$19),0%, IF(OR(B7='Security Related Factor'!$D$10,B7='Security Related Factor'!$D$11),IF(AND(D7<=1,F7="Invoice"),90%*G7, IF(OR(B7='Security Related Factor'!$D$10,B7='Security Related Factor'!$D$11),IF(AND(D7>1,D7<=3,F7="Invoice"),80%*G7, IF(OR(B7='Security Related Factor'!$D$10,B7='Security Related Factor'!$D$11),IF(AND(D7>4,F7="Invoice"),0%*G7, IF(OR(B7='Security Related Factor'!$D$10,B7='Security Related Factor'!$D$11),IF(AND(D7<=1,F7="Insurance"),80%*G7, IF(OR(B7='Security Related Factor'!$D$10,B7='Security Related Factor'!$D$11),IF(AND(D7>1,D7<=3,F7="Insurance"),70%*G7, IF(OR(B7='Security Related Factor'!$D$10,B7='Security Related Factor'!$D$11),IF(AND(D7>3,D7<=5,F7="Insurance"),60%*G7, IF(OR(B7='Security Related Factor'!$D$10,B7='Security Related Factor'!$D$11),IF(AND(D7>5,D7<=7,F7="Insurance"),50%*G7, IF(OR(B7='Security Related Factor'!$D$10,B7='Security Related Factor'!$D$11),IF(AND(D7>7,D7<=10,F7="Insurance"),40%*G7, IF(OR(B7='Security Related Factor'!$D$10,B7='Security Related Factor'!$D$11),IF(AND(D7>10,D7<=15,F7="Insurance"),25%*G7, IF(OR(B7='Security Related Factor'!$D$10,B7='Security Related Factor'!$D$11),IF(AND(D7>15,F7="Insurance"),0%*G7)))))))))))))))))))))) -> 1 | I7: =IF(B7="","",H7*E7) | J7: =B7 -> 0
A8: 5 | D8: =YEAR(TODAY())-C8 -> 2026 | G8: =IF(OR(B8='Security Related Factor'!$D$10,B8='Security Related Factor'!$D$11),IF(AND(D8>3,F8="Invoice"),0,1)) -> FALSE | H8: =IF(AND(B8<>'Security Related Factor'!$D$10,B8<>'Security Related Factor'!$D$11,B8<>'Security Related Factor'!$D$15,B8<>'Security Related Factor'!$D$16,B8<>'Security Related Factor'!$D$19),100%, IF(OR(B8='Security Related Factor'!$D$15,B8='Security Related Factor'!$D$16,B8='Security Related Factor'!$D$19),0%, IF(OR(B8='Security Related Factor'!$D$10,B8='Security Related Factor'!$D$11),IF(AND(D8<=1,F8="Invoice"),90%*G8, IF(OR(B8='Security Related Factor'!$D$10,B8='Security Related Factor'!$D$11),IF(AND(D8>1,D8<=3,F8="Invoice"),80%*G8, IF(OR(B8='Security Related Factor'!$D$10,B8='Security Related Factor'!$D$11),IF(AND(D8>4,F8="Invoice"),0%*G8, IF(OR(B8='Security Related Factor'!$D$10,B8='Security Related Factor'!$D$11),IF(AND(D8<=1,F8="Insurance"),80%*G8, IF(OR(B8='Security Related Factor'!$D$10,B8='Security Related Factor'!$D$11),IF(AND(D8>1,D8<=3,F8="Insurance"),70%*G8, IF(OR(B8='Security Related Factor'!$D$10,B8='Security Related Factor'!$D$11),IF(AND(D8>3,D8<=5,F8="Insurance"),60%*G8, IF(OR(B8='Security Related Factor'!$D$10,B8='Security Related Factor'!$D$11),IF(AND(D8>5,D8<=7,F8="Insurance"),50%*G8, IF(OR(B8='Security Related Factor'!$D$10,B8='Security Related Factor'!$D$11),IF(AND(D8>7,D8<=10,F8="Insurance"),40%*G8, IF(OR(B8='Security Related Factor'!$D$10,B8='Security Related Factor'!$D$11),IF(AND(D8>10,D8<=15,F8="Insurance"),25%*G8, IF(OR(B8='Security Related Factor'!$D$10,B8='Security Related Factor'!$D$11),IF(AND(D8>15,F8="Insurance"),0%*G8)))))))))))))))))))))) -> 1 | I8: =IF(B8="","",H8*E8) | J8: =B8 -> 0
A9: 6 | D9: =YEAR(TODAY())-C9 -> 2026 | G9: =IF(OR(B9='Security Related Factor'!$D$10,B9='Security Related Factor'!$D$11),IF(AND(D9>3,F9="Invoice"),0,1)) -> FALSE | H9: =IF(AND(B9<>'Security Related Factor'!$D$10,B9<>'Security Related Factor'!$D$11,B9<>'Security Related Factor'!$D$15,B9<>'Security Related Factor'!$D$16,B9<>'Security Related Factor'!$D$19),100%, IF(OR(B9='Security Related Factor'!$D$15,B9='Security Related Factor'!$D$16,B9='Security Related Factor'!$D$19),0%, IF(OR(B9='Security Related Factor'!$D$10,B9='Security Related Factor'!$D$11),IF(AND(D9<=1,F9="Invoice"),90%*G9, IF(OR(B9='Security Related Factor'!$D$10,B9='Security Related Factor'!$D$11),IF(AND(D9>1,D9<=3,F9="Invoice"),80%*G9, IF(OR(B9='Security Related Factor'!$D$10,B9='Security Related Factor'!$D$11),IF(AND(D9>4,F9="Invoice"),0%*G9, IF(OR(B9='Security Related Factor'!$D$10,B9='Security Related Factor'!$D$11),IF(AND(D9<=1,F9="Insurance"),80%*G9, IF(OR(B9='Security Related Factor'!$D$10,B9='Security Related Factor'!$D$11),IF(AND(D9>1,D9<=3,F9="Insurance"),70%*G9, IF(OR(B9='Security Related Factor'!$D$10,B9='Security Related Factor'!$D$11),IF(AND(D9>3,D9<=5,F9="Insurance"),60%*G9, IF(OR(B9='Security Related Factor'!$D$10,B9='Security Related Factor'!$D$11),IF(AND(D9>5,D9<=7,F9="Insurance"),50%*G9, IF(OR(B9='Security Related Factor'!$D$10,B9='Security Related Factor'!$D$11),IF(AND(D9>7,D9<=10,F9="Insurance"),40%*G9, IF(OR(B9='Security Related Factor'!$D$10,B9='Security Related Factor'!$D$11),IF(AND(D9>10,D9<=15,F9="Insurance"),25%*G9, IF(OR(B9='Security Related Factor'!$D$10,B9='Security Related Factor'!$D$11),IF(AND(D9>15,F9="Insurance"),0%*G9)))))))))))))))))))))) -> 1 | I9: =IF(B9="","",H9*E9) | J9: =B9 -> 0
A10: 7 | D10: =YEAR(TODAY())-C10 -> 2026 | G10: =IF(OR(B10='Security Related Factor'!$D$10,B10='Security Related Factor'!$D$11),IF(AND(D10>3,F10="Invoice"),0,1)) -> FALSE | H10: =IF(AND(B10<>'Security Related Factor'!$D$10,B10<>'Security Related Factor'!$D$11,B10<>'Security Related Factor'!$D$15,B10<>'Security Related Factor'!$D$16,B10<>'Security Related Factor'!$D$19),100%, IF(OR(B10='Security Related Factor'!$D$15,B10='Security Related Factor'!$D$16,B10='Security Related Factor'!$D$19),0%, IF(OR(B10='Security Related Factor'!$D$10,B10='Security Related Factor'!$D$11),IF(AND(D10<=1,F10="Invoice"),90%*G10, IF(OR(B10='Security Related Factor'!$D$10,B10='Security Related Factor'!$D$11),IF(AND(D10>1,D10<=3,F10="Invoice"),80%*G10, IF(OR(B10='Security Related Factor'!$D$10,B10='Security Related Factor'!$D$11),IF(AND(D10>4,F10="Invoice"),0%*G10, IF(OR(B10='Security Related Factor'!$D$10,B10='Security Related Factor'!$D$11),IF(AND(D10<=1,F10="Insurance"),80%*G10, IF(OR(B10='Security Related Factor'!$D$10,B10='Security Related Factor'!$D$11),IF(AND(D10>1,D10<=3,F10="Insurance"),70%*G10, IF(OR(B10='Security Related Factor'!$D$10,B10='Security Related Factor'!$D$11),IF(AND(D10>3,D10<=5,F10="Insurance"),60%*G10, IF(OR(B10='Security Related Factor'!$D$10,B10='Security Related Factor'!$D$11),IF(AND(D10>5,D10<=7,F10="Insurance"),50%*G10, IF(OR(B10='Security Related Factor'!$D$10,B10='Security Related Factor'!$D$11),IF(AND(D10>7,D10<=10,F10="Insurance"),40%*G10, IF(OR(B10='Security Related Factor'!$D$10,B10='Security Related Factor'!$D$11),IF(AND(D10>10,D10<=15,F10="Insurance"),25%*G10, IF(OR(B10='Security Related Factor'!$D$10,B10='Security Related Factor'!$D$11),IF(AND(D10>15,F10="Insurance"),0%*G10)))))))))))))))))))))) -> 1 | I10: =IF(B10="","",H10*E10) | J10: =B10 -> 0
A11: 8 | D11: =YEAR(TODAY())-C11 -> 2026 | G11: =IF(OR(B11='Security Related Factor'!$D$10,B11='Security Related Factor'!$D$11),IF(AND(D11>3,F11="Invoice"),0,1)) -> FALSE | H11: =IF(AND(B11<>'Security Related Factor'!$D$10,B11<>'Security Related Factor'!$D$11,B11<>'Security Related Factor'!$D$15,B11<>'Security Related Factor'!$D$16,B11<>'Security Related Factor'!$D$19),100%, IF(OR(B11='Security Related Factor'!$D$15,B11='Security Related Factor'!$D$16,B11='Security Related Factor'!$D$19),0%, IF(OR(B11='Security Related Factor'!$D$10,B11='Security Related Factor'!$D$11),IF(AND(D11<=1,F11="Invoice"),90%*G11, IF(OR(B11='Security Related Factor'!$D$10,B11='Security Related Factor'!$D$11),IF(AND(D11>1,D11<=3,F11="Invoice"),80%*G11, IF(OR(B11='Security Related Factor'!$D$10,B11='Security Related Factor'!$D$11),IF(AND(D11>4,F11="Invoice"),0%*G11, IF(OR(B11='Security Related Factor'!$D$10,B11='Security Related Factor'!$D$11),IF(AND(D11<=1,F11="Insurance"),80%*G11, IF(OR(B11='Security Related Factor'!$D$10,B11='Security Related Factor'!$D$11),IF(AND(D11>1,D11<=3,F11="Insurance"),70%*G11, IF(OR(B11='Security Related Factor'!$D$10,B11='Security Related Factor'!$D$11),IF(AND(D11>3,D11<=5,F11="Insurance"),60%*G11, IF(OR(B11='Security Related Factor'!$D$10,B11='Security Related Factor'!$D$11),IF(AND(D11>5,D11<=7,F11="Insurance"),50%*G11, IF(OR(B11='Security Related Factor'!$D$10,B11='Security Related Factor'!$D$11),IF(AND(D11>7,D11<=10,F11="Insurance"),40%*G11, IF(OR(B11='Security Related Factor'!$D$10,B11='Security Related Factor'!$D$11),IF(AND(D11>10,D11<=15,F11="Insurance"),25%*G11, IF(OR(B11='Security Related Factor'!$D$10,B11='Security Related Factor'!$D$11),IF(AND(D11>15,F11="Insurance"),0%*G11)))))))))))))))))))))) -> 1 | I11: =IF(B11="","",H11*E11) | J11: =B11 -> 0
A12: 9 | D12: =YEAR(TODAY())-C12 -> 2026 | G12: =IF(OR(B12='Security Related Factor'!$D$10,B12='Security Related Factor'!$D$11),IF(AND(D12>3,F12="Invoice"),0,1)) -> FALSE | H12: =IF(AND(B12<>'Security Related Factor'!$D$10,B12<>'Security Related Factor'!$D$11,B12<>'Security Related Factor'!$D$15,B12<>'Security Related Factor'!$D$16,B12<>'Security Related Factor'!$D$19),100%, IF(OR(B12='Security Related Factor'!$D$15,B12='Security Related Factor'!$D$16,B12='Security Related Factor'!$D$19),0%, IF(OR(B12='Security Related Factor'!$D$10,B12='Security Related Factor'!$D$11),IF(AND(D12<=1,F12="Invoice"),90%*G12, IF(OR(B12='Security Related Factor'!$D$10,B12='Security Related Factor'!$D$11),IF(AND(D12>1,D12<=3,F12="Invoice"),80%*G12, IF(OR(B12='Security Related Factor'!$D$10,B12='Security Related Factor'!$D$11),IF(AND(D12>4,F12="Invoice"),0%*G12, IF(OR(B12='Security Related Factor'!$D$10,B12='Security Related Factor'!$D$11),IF(AND(D12<=1,F12="Insurance"),80%*G12, IF(OR(B12='Security Related Factor'!$D$10,B12='Security Related Factor'!$D$11),IF(AND(D12>1,D12<=3,F12="Insurance"),70%*G12, IF(OR(B12='Security Related Factor'!$D$10,B12='Security Related Factor'!$D$11),IF(AND(D12>3,D12<=5,F12="Insurance"),60%*G12, IF(OR(B12='Security Related Factor'!$D$10,B12='Security Related Factor'!$D$11),IF(AND(D12>5,D12<=7,F12="Insurance"),50%*G12, IF(OR(B12='Security Related Factor'!$D$10,B12='Security Related Factor'!$D$11),IF(AND(D12>7,D12<=10,F12="Insurance"),40%*G12, IF(OR(B12='Security Related Factor'!$D$10,B12='Security Related Factor'!$D$11),IF(AND(D12>10,D12<=15,F12="Insurance"),25%*G12, IF(OR(B12='Security Related Factor'!$D$10,B12='Security Related Factor'!$D$11),IF(AND(D12>15,F12="Insurance"),0%*G12)))))))))))))))))))))) -> 1 | I12: =IF(B12="","",H12*E12) | J12: =B12 -> 0
A13: 10 | D13: =YEAR(TODAY())-C13 -> 2026 | G13: =IF(OR(B13='Security Related Factor'!$D$10,B13='Security Related Factor'!$D$11),IF(AND(D13>3,F13="Invoice"),0,1)) -> FALSE | H13: =IF(AND(B13<>'Security Related Factor'!$D$10,B13<>'Security Related Factor'!$D$11,B13<>'Security Related Factor'!$D$15,B13<>'Security Related Factor'!$D$16,B13<>'Security Related Factor'!$D$19),100%, IF(OR(B13='Security Related Factor'!$D$15,B13='Security Related Factor'!$D$16,B13='Security Related Factor'!$D$19),0%, IF(OR(B13='Security Related Factor'!$D$10,B13='Security Related Factor'!$D$11),IF(AND(D13<=1,F13="Invoice"),90%*G13, IF(OR(B13='Security Related Factor'!$D$10,B13='Security Related Factor'!$D$11),IF(AND(D13>1,D13<=3,F13="Invoice"),80%*G13, IF(OR(B13='Security Related Factor'!$D$10,B13='Security Related Factor'!$D$11),IF(AND(D13>4,F13="Invoice"),0%*G13, IF(OR(B13='Security Related Factor'!$D$10,B13='Security Related Factor'!$D$11),IF(AND(D13<=1,F13="Insurance"),80%*G13, IF(OR(B13='Security Related Factor'!$D$10,B13='Security Related Factor'!$D$11),IF(AND(D13>1,D13<=3,F13="Insurance"),70%*G13, IF(OR(B13='Security Related Factor'!$D$10,B13='Security Related Factor'!$D$11),IF(AND(D13>3,D13<=5,F13="Insurance"),60%*G13, IF(OR(B13='Security Related Factor'!$D$10,B13='Security Related Factor'!$D$11),IF(AND(D13>5,D13<=7,F13="Insurance"),50%*G13, IF(OR(B13='Security Related Factor'!$D$10,B13='Security Related Factor'!$D$11),IF(AND(D13>7,D13<=10,F13="Insurance"),40%*G13, IF(OR(B13='Security Related Factor'!$D$10,B13='Security Related Factor'!$D$11),IF(AND(D13>10,D13<=15,F13="Insurance"),25%*G13, IF(OR(B13='Security Related Factor'!$D$10,B13='Security Related Factor'!$D$11),IF(AND(D13>15,F13="Insurance"),0%*G13)))))))))))))))))))))) -> 1 | I13: =IF(B13="","",H13*E13) | J13: =B13 -> 0
A14: 11 | D14: =YEAR(TODAY())-C14 -> 2026 | G14: =IF(OR(B14='Security Related Factor'!$D$10,B14='Security Related Factor'!$D$11),IF(AND(D14>3,F14="Invoice"),0,1)) -> FALSE | H14: =IF(AND(B14<>'Security Related Factor'!$D$10,B14<>'Security Related Factor'!$D$11,B14<>'Security Related Factor'!$D$15,B14<>'Security Related Factor'!$D$16,B14<>'Security Related Factor'!$D$19),100%, IF(OR(B14='Security Related Factor'!$D$15,B14='Security Related Factor'!$D$16,B14='Security Related Factor'!$D$19),0%, IF(OR(B14='Security Related Factor'!$D$10,B14='Security Related Factor'!$D$11),IF(AND(D14<=1,F14="Invoice"),90%*G14, IF(OR(B14='Security Related Factor'!$D$10,B14='Security Related Factor'!$D$11),IF(AND(D14>1,D14<=3,F14="Invoice"),80%*G14, IF(OR(B14='Security Related Factor'!$D$10,B14='Security Related Factor'!$D$11),IF(AND(D14>4,F14="Invoice"),0%*G14, IF(OR(B14='Security Related Factor'!$D$10,B14='Security Related Factor'!$D$11),IF(AND(D14<=1,F14="Insurance"),80%*G14, IF(OR(B14='Security Related Factor'!$D$10,B14='Security Related Factor'!$D$11),IF(AND(D14>1,D14<=3,F14="Insurance"),70%*G14, IF(OR(B14='Security Related Factor'!$D$10,B14='Security Related Factor'!$D$11),IF(AND(D14>3,D14<=5,F14="Insurance"),60%*G14, IF(OR(B14='Security Related Factor'!$D$10,B14='Security Related Factor'!$D$11),IF(AND(D14>5,D14<=7,F14="Insurance"),50%*G14, IF(OR(B14='Security Related Factor'!$D$10,B14='Security Related Factor'!$D$11),IF(AND(D14>7,D14<=10,F14="Insurance"),40%*G14, IF(OR(B14='Security Related Factor'!$D$10,B14='Security Related Factor'!$D$11),IF(AND(D14>10,D14<=15,F14="Insurance"),25%*G14, IF(OR(B14='Security Related Factor'!$D$10,B14='Security Related Factor'!$D$11),IF(AND(D14>15,F14="Insurance"),0%*G14)))))))))))))))))))))) -> 1 | I14: =IF(B14="","",H14*E14) | J14: =B14 -> 0
A15: 12 | D15: =YEAR(TODAY())-C15 -> 2026 | G15: =IF(OR(B15='Security Related Factor'!$D$10,B15='Security Related Factor'!$D$11),IF(AND(D15>3,F15="Invoice"),0,1)) -> FALSE | H15: =IF(AND(B15<>'Security Related Factor'!$D$10,B15<>'Security Related Factor'!$D$11,B15<>'Security Related Factor'!$D$15,B15<>'Security Related Factor'!$D$16,B15<>'Security Related Factor'!$D$19),100%, IF(OR(B15='Security Related Factor'!$D$15,B15='Security Related Factor'!$D$16,B15='Security Related Factor'!$D$19),0%, IF(OR(B15='Security Related Factor'!$D$10,B15='Security Related Factor'!$D$11),IF(AND(D15<=1,F15="Invoice"),90%*G15, IF(OR(B15='Security Related Factor'!$D$10,B15='Security Related Factor'!$D$11),IF(AND(D15>1,D15<=3,F15="Invoice"),80%*G15, IF(OR(B15='Security Related Factor'!$D$10,B15='Security Related Factor'!$D$11),IF(AND(D15>4,F15="Invoice"),0%*G15, IF(OR(B15='Security Related Factor'!$D$10,B15='Security Related Factor'!$D$11),IF(AND(D15<=1,F15="Insurance"),80%*G15, IF(OR(B15='Security Related Factor'!$D$10,B15='Security Related Factor'!$D$11),IF(AND(D15>1,D15<=3,F15="Insurance"),70%*G15, IF(OR(B15='Security Related Factor'!$D$10,B15='Security Related Factor'!$D$11),IF(AND(D15>3,D15<=5,F15="Insurance"),60%*G15, IF(OR(B15='Security Related Factor'!$D$10,B15='Security Related Factor'!$D$11),IF(AND(D15>5,D15<=7,F15="Insurance"),50%*G15, IF(OR(B15='Security Related Factor'!$D$10,B15='Security Related Factor'!$D$11),IF(AND(D15>7,D15<=10,F15="Insurance"),40%*G15, IF(OR(B15='Security Related Factor'!$D$10,B15='Security Related Factor'!$D$11),IF(AND(D15>10,D15<=15,F15="Insurance"),25%*G15, IF(OR(B15='Security Related Factor'!$D$10,B15='Security Related Factor'!$D$11),IF(AND(D15>15,F15="Insurance"),0%*G15)))))))))))))))))))))) -> 1 | I15: =IF(B15="","",H15*E15) | J15: =B15 -> 0
A16: 13 | D16: =YEAR(TODAY())-C16 -> 2026 | G16: =IF(OR(B16='Security Related Factor'!$D$10,B16='Security Related Factor'!$D$11),IF(AND(D16>3,F16="Invoice"),0,1)) -> FALSE | H16: =IF(AND(B16<>'Security Related Factor'!$D$10,B16<>'Security Related Factor'!$D$11,B16<>'Security Related Factor'!$D$15,B16<>'Security Related Factor'!$D$16,B16<>'Security Related Factor'!$D$19),100%, IF(OR(B16='Security Related Factor'!$D$15,B16='Security Related Factor'!$D$16,B16='Security Related Factor'!$D$19),0%, IF(OR(B16='Security Related Factor'!$D$10,B16='Security Related Factor'!$D$11),IF(AND(D16<=1,F16="Invoice"),90%*G16, IF(OR(B16='Security Related Factor'!$D$10,B16='Security Related Factor'!$D$11),IF(AND(D16>1,D16<=3,F16="Invoice"),80%*G16, IF(OR(B16='Security Related Factor'!$D$10,B16='Security Related Factor'!$D$11),IF(AND(D16>4,F16="Invoice"),0%*G16, IF(OR(B16='Security Related Factor'!$D$10,B16='Security Related Factor'!$D$11),IF(AND(D16<=1,F16="Insurance"),80%*G16, IF(OR(B16='Security Related Factor'!$D$10,B16='Security Related Factor'!$D$11),IF(AND(D16>1,D16<=3,F16="Insurance"),70%*G16, IF(OR(B16='Security Related Factor'!$D$10,B16='Security Related Factor'!$D$11),IF(AND(D16>3,D16<=5,F16="Insurance"),60%*G16, IF(OR(B16='Security Related Factor'!$D$10,B16='Security Related Factor'!$D$11),IF(AND(D16>5,D16<=7,F16="Insurance"),50%*G16, IF(OR(B16='Security Related Factor'!$D$10,B16='Security Related Factor'!$D$11),IF(AND(D16>7,D16<=10,F16="Insurance"),40%*G16, IF(OR(B16='Security Related Factor'!$D$10,B16='Security Related Factor'!$D$11),IF(AND(D16>10,D16<=15,F16="Insurance"),25%*G16, IF(OR(B16='Security Related Factor'!$D$10,B16='Security Related Factor'!$D$11),IF(AND(D16>15,F16="Insurance"),0%*G16)))))))))))))))))))))) -> 1 | I16: =IF(B16="","",H16*E16) | J16: =B16 -> 0
... A37: 34 | D37: =YEAR(TODAY())-C37 -> 2026 | G37: =IF(OR(B37='Security Related Factor'!$D$10,B37='Security Related Factor'!$D$11),IF(AND(D37>3,F37="Invoice"),0,1)) -> FALSE | H37: =IF(AND(B37<>'Security Related Factor'!$D$10,B37<>'Security Related Factor'!$D$11,B37<>'Security Related Factor'!$D$15,B37<>'Security Related Factor'!$D$16,B37<>'Security Related Factor'!$D$19),100%, IF(OR(B37='Security Related Factor'!$D$15,B37='Security Related Factor'!$D$16,B37='Security Related Factor'!$D$19),0%, IF(OR(B37='Security Related Factor'!$D$10,B37='Security Related Factor'!$D$11),IF(AND(D37<=1,F37="Invoice"),90%*G37, IF(OR(B37='Security Related Factor'!$D$10,B37='Security Related Factor'!$D$11),IF(AND(D37>1,D37<=3,F37="Invoice"),80%*G37, IF(OR(B37='Security Related Factor'!$D$10,B37='Security Related Factor'!$D$11),IF(AND(D37>4,F37="Invoice"),0%*G37, IF(OR(B37='Security Related Factor'!$D$10,B37='Security Related Factor'!$D$11),IF(AND(D37<=1,F37="Insurance"),80%*G37, IF(OR(B37='Security Related Factor'!$D$10,B37='Security Related Factor'!$D$11),IF(AND(D37>1,D37<=3,F37="Insurance"),70%*G37, IF(OR(B37='Security Related Factor'!$D$10,B37='Security Related Factor'!$D$11),IF(AND(D37>3,D37<=5,F37="Insurance"),60%*G37, IF(OR(B37='Security Related Factor'!$D$10,B37='Security Related Factor'!$D$11),IF(AND(D37>5,D37<=7,F37="Insurance"),50%*G37, IF(OR(B37='Security Related Factor'!$D$10,B37='Security Related Factor'!$D$11),IF(AND(D37>7,D37<=10,F37="Insurance"),40%*G37, IF(OR(B37='Security Related Factor'!$D$10,B37='Security Related Factor'!$D$11),IF(AND(D37>10,D37<=15,F37="Insurance"),25%*G37, IF(OR(B37='Security Related Factor'!$D$10,B37='Security Related Factor'!$D$11),IF(AND(D37>15,F37="Insurance"),0%*G37)))))))))))))))))))))) -> 1 | I37: =IF(B37="","",H37*E37) | J37: =B37 -> 0
I38: =SUM(I4:I37) -> 0
A39: Collateral that shares maximum Percentage | I39: =IF(SUM(I4:I37)=0,"",VLOOKUP(MAX(I4:I37),I4:J37,2,0))
B42: Prepared by | C42: _____________________

Sheet WC - CGS
B1: Working Capital Determination
B2: Cost of Goods Sold Method
B4: Operation Year | C4: ='Financial Statement'!B38 -> July 07, 2025 G.C | D4: ='Financial Statement'!C38 -> July 7, 2024 G.C | E4: ='Financial Statement'!D38 -> July 7, 2023 G.C | F4: ='Financial Statement'!E38 -> July 7, 2022 G.C | G4: Average % Growth
B5: Revenue | C5: ='Financial Statement'!B40 -> 0 | D5: ='Financial Statement'!C40 -> 0 | E5: ='Financial Statement'!D40 -> 0 | F5: ='Financial Statement'!E40 -> 0 | G5: =AVERAGE(C5:F5) -> 0
B6: CGS | C6: ='Financial Statement'!B41 -> 0 | D6: ='Financial Statement'!C41 -> 0 | E6: ='Financial Statement'!D41 -> 0 | F6: ='Financial Statement'!E41 -> 0 | G6: =AVERAGE(C6:F6) -> 0
B7: Expenses | C7: ='Financial Statement'!B43 -> 0 | D7: ='Financial Statement'!C43 -> 0 | E7: ='Financial Statement'!D43 -> 0 | F7: ='Financial Statement'!E43 -> 0 | G7: =AVERAGE(C7:F7) -> 0
B8: CGS to Total Sales | C8: =C6/C5 -> #DIV/0! | D8: =D6/D5 -> #DIV/0! | E8: =E6/E5 -> #DIV/0! | F8: =F6/F5 -> #DIV/0! | G8: =AVERAGE(C8:F8) -> #DIV/0!
B9: Sales growth rate | C9: =(C5-D5)/D5 -> #DIV/0! | D9: =(D5-E5)/E5 -> #DIV/0! | E9: =(E5-F5)/F5 -> #DIV/0! | G9: =AVERAGE(C9:F9) -> #DIV/0!
B10: Expense growth rate | C10: =(C7-D7)/D7 -> #DIV/0! | D10: =(D7-E7)/E7 -> #DIV/0! | E10: =(E7-F7)/F7 -> #DIV/0! | G10: =AVERAGE(C10:F10) -> #DIV/0!
B13: Description | C13: Working Capital
B14: Forcasted Sales Revenue | C14: =G5+G5*G9 -> #DIV/0!
B15: Average CGS to total sales | C15: =G8 -> #DIV/0!
B16: Forecasted CGS | C16: =C15*C14 -> #DIV/0!
B17: Expenses | C17: =G7+G7*G10 -> #DIV/0!
B18: Total Annual Working Capital | C18: =C17+C16 -> #DIV/0!
B19: Working Capital Cycle (months) | C19: ='Data Validation'!C71 -> 0
B20: Working Capital for one cycle | C20: =C18/C19 -> #DIV/0!
B21: Less: Net Current Asset) | C21: ='Financial Statement'!B32 -> 0
B22: Less: Existing Facility with Banks
B23: Net working capital required | C23: =C20-C21-C22 -> #DIV/0!
B26: Prepared by | C26: _____________________

Sheet WC - Cash Flow
B1: Working Capital Determination
B2: Cash Flow Method
B5: Description | C5: Working Capital
B6: Forecasted Annual Cash Inflows
B7: Forecasted Annual Cash Outflows
B8: Total Annual Working Capital | C8: =C7 -> 0
B9: Working Capital Cycle (months) | C9: ='Data Validation'!C71 -> 0
B10: Working Capital for one cycle | C10: =C8/C9 -> #DIV/0!
B11: Less: Net Current Asset) | C11: ='Financial Statement'!B32 -> 0
B12: Less: Existing Facility with Banks
B13: Net working capital required | C13: =C10-C11-C12 -> #DIV/0!
B16: Prepared by | C16: _____________________

Sheet Data Validation
B2: Name of Customer
D3: Justification | E3: Source
B4: Sector
B5: Sub-sector
B6: Line of business
B7: Amount Requested
B8: Product Requested
A10: 1 | B10: Business/Industry and form of organization
D11: =D3 -> Justification | E11: Source
A12: 1.1 | B12: Business/Industry outlook of the customer
A13: 1.2 | B13: Market competition/market
A14: 1.3 | B14: Form of Organization
A16: 2 | B16: Financial Ratios
B17: ='Business Strength Score'!B5 -> Activity Ratio | C17: ='Financial Statement'!F55 -> #DIV/0!
B18: ='Business Strength Score'!B6 -> Leverage (Total Debt to total asset) | C18: ='Financial Statement'!B63 -> #DIV/0!
B19: ='Business Strength Score'!B7 -> Liquidity (Current Ratio = CA/CL) | C19: ='Financial Statement'!B60 -> #DIV/0!
B20: ='Business Strength Score'!B8 -> Return on Asset =Net Income after tax /Total asset) | C20: ='Financial Statement'!B66 -> #DIV/0!
B21: ='Business Strength Score'!B9 -> Operating profit Margin(Operating profit/Total Sales) | C21: ='Financial Statement'!B69 -> #DIV/0!
B22: ='Business Strength Score'!B10 -> Debt Service Coverage Ratio (Net income after tax/Interest expenses) | C22: =IF('Financial Statement'!B47="","",'Financial Statement'!B68)
B23: ='Business Strength Score'!B11 -> Inventory Turnover Ratio (CGS/Average Inventory) | C23: ='Financial Statement'!B56 -> #DIV/0!
B24: ='Business Strength Score'!B12 -> Return on Equity (Net Income / Equity) | C24: ='Financial Statement'!B67 -> #DIV/0!
B25: ='Business Strength Score'!B13 -> Quality of Financial Statement | C25: ='Financial Statement'!B51 -> 0
B26: ='Business Strength Score'!B14 -> Negative Values | C26: ='Financial Statement'!B52 -> 0
B27: ='Business Strength Score'!B15 -> Total Equity/Total Asset | C27: ='Financial Statement'!B62 -> #DIV/0!
A28: 3 | B28: Credit History
A29: 2.1 | B29: Loan Facility History | C29: YES
A30: 2.1.1 | B30: Overdraft Utilization | C30: =IF(C31="NO","NO",IF(C29="NO","NO","YES")) -> NO
B31: Overdraft Account Number | C31: =IF(AND(C29="YES",'OD TURNOVER'!B4>0),'OD TURNOVER'!B4,"NO") -> NO
B32: Overdraft Swing (Highest Debit %age) | C32: =IF(C31="NO","NA",-MIN('OD SWING'!B14:B26)/('OD SWING'!B6)) -> NA
B33: Overdraft Swing (Lowest Debit %age) | C33: =IF(C31="NO","NA",-MAX('OD SWING'!D14:D26)/('OD SWING'!B6)) -> NA
B34: Overdraft Turnover | C34: {=IF(C31="NO","NA",SUM('OD TURNOVER'!B13:B25/'OD TURNOVER'!B6))} -> NA
B35: Overdraft Current Status Classifcation | C35: =IF(C30="YES",'OD TURNOVER'!B10,"NA") -> NA
A36: 2.1.2 | B36: Letter of Credit
B37: Average settlement of import L/C facility
A38: 2.1.3 | B38: Merchandise Loan Facility | C38: =IF(C39="NO","NO",IF(C29="NO","NO","YES")) -> NO
B39: Merchandise Loan Account Number | C39: =IF(AND(C29="YES",'Merchandise Turnover'!C7>0),'Merchandise Turnover'!C7,"NO") -> NO
B40: Settlement of Merchandise Loan
B41: Turn-over | C41: {=IF(C38="NO","NA",SUM('Merchandise Turnover'!D14:D26/'Merchandise Turnover'!C8))} -> NA
A42: 2.1.4 | B42: Pre-shipment Export Credit | C42: =IF(C43="NO","NO",IF(C29="NO","NO","YES")) -> NO
B43: Pre-Shipment Loan Account Number | C43: =IF(AND(C29="YES",'Pre-Shipment Turnover'!C7>0),'Pre-Shipment Turnover'!C7,"NO") -> NO
...

Sheet Business Strength Score
A2: Credit Risk Rating and Scoring Template
A4: Perspective | B4: Description | C4: Weight | D4: Score | F4: Mark
A5: Financial (40%) | B5: Activity Ratio | C5: ='Financial 40'!O5 -> 0.03 | D5: =IF(AND('Data Validation'!C4='Financial 40'!C3,'Financial Statement'!F55>='Financial 40'!D5),'Financial 40'!O5, IF(AND('Data Validation'!C4='Financial 40'!C3,'Financial Statement'!F55<'Financial 40'!D6,'Financial Statement'!F55>='Financial 40'!C6),'Financial 40'!O6, IF(AND('Data Validation'!C4='Financial 40'!C3,'Financial Statement'!F55<'Financial 40'!D7,'Financial Statement'!F55>='Financial 40'!C7),'Financial 40'!O7, IF(AND('Data Validation'!C4='Financial 40'!C3,'Financial Statement'!F55<'Financial 40'!D8),'Financial 40'!O8, IF(AND('Data Validation'!C4='Financial 40'!E3,'Financial Statement'!F55>='Financial 40'!F5),'Financial 40'!O5, IF(AND('Data Validation'!C4='Financial 40'!E3,'Financial Statement'!F55<'Financial 40'!F6,'Financial Statement'!F55>='Financial 40'!E6),'Financial 40'!O6, IF(AND('Data Validation'!C4='Financial 40'!E3,'Financial Statement'!F55<'Financial 40'!F7,'Financial Statement'!F55>='Financial 40'!E7),'Financial 40'!O7, IF(AND('Data Validation'!C4='Financial 40'!E3,'Financial Statement'!F55<'Financial 40'!F8),'Financial 40'!O8, IF(AND('Data Validation'!C4='Financial 40'!G3,'Financial Statement'!F55>='Financial 40'!H5),'Financial 40'!O5, IF(AND('Data Validation'!C4='Financial 40'!G3,'Financial Statement'!F55<'Financial 40'!H6,'Financial Statement'!F55>='Financial 40'!G6),'Financial 40'!O6, IF(AND('Data Validation'!C4='Financial 40'!G3,'Financial Statement'!F55<'Financial 40'!H7,'Financial Statement'!F55>='Financial 40'!G7),'Financial 40'!O7, IF(AND('Data Validation'!C4='Financial 40'!G3,'Financial Statement'!F55<'Financial 40'!H8),'Financial 40'!O8, IF(AND('Data Validation'!C4='Financial 40'!I3,'Financial Statement'!F55>='Financial 40'!J5),'Financial 40'!O5, IF(AND('Data Validation'!C4='Financial 40'!I3,'Financial Statement'!F55<'Financial 40'!J6,'Financial Statement'!F55>='Financial 40'!I6),'Financial 40'!O6, IF(AND('Data Validation'!C4='Financial 40'!I3,'Financial Statement'!F55<'Financial 40'!J7,'Financial Statement'!F55>='Financial 40'!I7),'Financial 40'!O7, IF(AND('Data Validation'!C4='Financial 40'!I3,'Financial Statement'!F55<'Financial 40'!J8),'Financial 40'!O8, IF(AND('Data Validation'!C4='Financial 40'!K3,'Financial Statement'!F55>='Financial 40'!L5),'Financial 40'!O5, IF(AND('Data Validation'!C4='Financial 40'!K3,'Financial Statement'!F55<'Financial 40'!L6,'Financial Statement'!F55>='Financial 40'!K6),'Financial 40'!O6, IF(AND('Data Validation'!C4='Financial 40'!K3,'Financial Statement'!F55<'Financial 40'!L7,'Financial Statement'!F55>='Financial 40'!K7),'Financial 40'!O7, IF(AND('Data Validation'!C4='Financial 40'!K3,'Financial Statement'!F55<'Financial 40'!L8),'Financial 40'!O8, IF(AND('Data Validation'!C4='Financial 40'!M3,'Financial Statement'!F55>='Financial 40'!N5),'Financial 40'!O5, IF(AND('Data Validation'!C4='Financial 40'!M3,'Financial Statement'!F55<'Financial 40'!N6,'Financial Statement'!F55>='Financial 40'!M6),'Financial 40'!O6, IF(AND('Data Validation'!C4='Financial 40'!M3,'Financial Statement'!F55<'Financial 40'!N7,'Financial Statement'!F55>='Financial 40'!M7),'Financial 40'!O7, IF(AND('Data Validation'!C4='Financial 40'!M3,'Financial Statement'!F55<'Financial 40'!N8),'Financial 40'!O8)))))))))))))))))))))))) -> #DIV/0! | F5: =SUM(D5:D15) -> #DIV/0!
B6: Leverage (Total Debt to total asset) | C6: ='Financial 40'!O9 -> 0.06 | D6: =IF(AND('Data Validation'!C4='Financial 40'!C3,'Financial Statement'!B63<='Financial 40'!D9),'Financial 40'!O9, IF(AND('Data Validation'!C4='Financial 40'!C3,'Financial Statement'!B63>'Financial 40'!D10,'Financial Statement'!B63<='Financial 40'!C10),'Financial 40'!O10, IF(AND('Data Validation'!C4='Financial 40'!C3,'Financial Statement'!B63>'Financial 40'!D11,'Financial Statement'!B63<='Financial 40'!C11),'Financial 40'!O11, IF(AND('Data Validation'!C4='Financial 40'!C3,'Financial Statement'!B63>'Financial 40'!D12),'Financial 40'!O12, IF(AND('Data Validation'!C4='Financial 40'!E3,'Financial Statement'!B63<='Financial 40'!F9),'Financial 40'!O9, IF(AND('Data Validation'!C4='Financial 40'!E3,'Financial Statement'!B63>'Financial 40'!F10,'Financial Statement'!B63<='Financial 40'!E10),'Financial 40'!O10, IF(AND('Data Validation'!C4='Financial 40'!E3,'Financial Statement'!B63>'Financial 40'!F11,'Financial Statement'!B63<='Financial 40'!E11),'Financial 40'!O11, IF(AND('Data Validation'!C4='Financial 40'!E3,'Financial Statement'!B63>'Financial 40'!F12),'Financial 40'!O12, IF(AND('Data Validation'!C4='Financial 40'!G3,'Financial Statement'!B63<='Financial 40'!H9),'Financial 40'!O9, IF(AND('Data Validation'!C4='Financial 40'!G3,'Financial Statement'!B63>'Financial 40'!H10,'Financial Statement'!B63<='Financial 40'!G10),'Financial 40'!O10, IF(AND('Data Validation'!C4='Financial 40'!G3,'Financial Statement'!B63>'Financial 40'!H11,'Financial Statement'!B63<='Financial 40'!G11),'Financial 40'!O11, IF(AND('Data Validation'!C4='Financial 40'!G3,'Financial Statement'!B63>'Financial 40'!H12),'Financial 40'!O12, IF(AND('Data Validation'!C4='Financial 40'!I3,'Financial Statement'!B63<='Financial 40'!J9),'Financial 40'!O9, IF(AND('Data Validation'!C4='Financial 40'!I3,'Financial Statement'!B63>'Financial 40'!J10,'Financial Statement'!B63<='Financial 40'!I10),'Financial 40'!O10, IF(AND('Data Validation'!C4='Financial 40'!I3,'Financial Statement'!B63>'Financial 40'!J11,'Financial Statement'!B63<='Financial 40'!I11),'Financial 40'!O11, IF(AND('Data Validation'!C4='Financial 40'!I3,'Financial Statement'!B63>'Financial 40'!J12),'Financial 40'!O12, IF(AND('Data Validation'!C4='Financial 40'!K3,'Financial Statement'!B63<='Financial 40'!L9),'Financial 40'!O9, IF(AND('Data Validation'!C4='Financial 40'!K3,'Financial Statement'!B63>'Financial 40'!L10,'Financial Statement'!B63<='Financial 40'!K10),'Financial 40'!O10, IF(AND('Data Validation'!C4='Financial 40'!K3,'Financial Statement'!B63>'Financial 40'!L11,'Financial Statement'!B63<='Financial 40'!K11),'Financial 40'!O11, IF(AND('Data Validation'!C4='Financial 40'!K3,'Financial Statement'!B63>'Financial 40'!L12),'Financial 40'!O12, IF(AND('Data Validation'!C4='Financial 40'!M3,'Financial Statement'!B63<='Financial 40'!N9),'Financial 40'!O9, IF(AND('Data Validation'!C4='Financial 40'!M3,'Financial Statement'!B63>'Financial 40'!N10,'Financial Statement'!B63<='Financial 40'!M10),'Financial 40'!O10, IF(AND('Data Validation'!C4='Financial 40'!M3,'Financial Statement'!B63>'Financial 40'!N11,'Financial Statement'!B63<='Financial 40'!M11),'Financial 40'!O11, IF(AND('Data Validation'!C4='Financial 40'!M3,'Financial Statement'!B63>'Financial 40'!N12),'Financial 40'!O12)))))))))))))))))))))))) -> #DIV/0!
B7: Liquidity (Current Ratio = CA/CL) | C7: ='Financial 40'!O13 -> 0.05 | D7: =IF('Financial Statement'!B21=0,5%, IF(AND('Data Validation'!C4='Financial 40'!C3,'Financial Statement'!B60<='Financial 40'!D13),'Financial 40'!O13, IF(AND('Data Validation'!C4='Financial 40'!C3,'Financial Statement'!B60>'Financial 40'!D14,'Financial Statement'!B60<='Financial 40'!C14),'Financial 40'!O14, IF(AND('Data Validation'!C4='Financial 40'!C3,'Financial Statement'!B60>'Financial 40'!D15,'Financial Statement'!B60<='Financial 40'!C15),'Financial 40'!O15, IF(AND('Data Validation'!C4='Financial 40'!C3,'Financial Statement'!B60>'Financial 40'!D16,'Financial Statement'!B60<='Financial 40'!C16),'Financial 40'!O16, IF(AND('Data Validation'!C4='Financial 40'!C3,'Financial Statement'!B60>'Financial 40'!D17),'Financial 40'!O17, IF(AND('Data Validation'!C4='Financial 40'!E3,'Financial Statement'!B60<='Financial 40'!F13),'Financial 40'!O13, IF(AND('Data Validation'!C4='Financial 40'!E3,'Financial Statement'!B60>'Financial 40'!F14,'Financial Statement'!B60<='Financial 40'!E14),'Financial 40'!O14, IF(AND('Data Validation'!C4='Financial 40'!E3,'Financial Statement'!B60>'Financial 40'!F15,'Financial Statement'!B60<='Financial 40'!E15),'Financial 40'!O15, IF(AND('Data Validation'!C4='Financial 40'!E3,'Financial Statement'!B60>'Financial 40'!F16,'Financial Statement'!B60<='Financial 40'!E16),'Financial 40'!O16, IF(AND('Data Validation'!C4='Financial 40'!E3,'Financial Statement'!B60>'Financial 40'!F17),'Financial 40'!O17, IF(AND('Data Validation'!C4='Financial 40'!G3,'Financial Statement'!B60<='Financial 40'!H13),'Financial 40'!O13, IF(AND('Data Validation'!C4='Financial 40'!G3,'Financial Statement'!B60>'Financial 40'!H14,'Financial Statement'!B60<='Financial 40'!G14),'Financial 40'!O14, IF(AND('Data Validation'!C4='Financial 40'!G3,'Financial Statement'!B60>'Financial 40'!H15,'Financial Statement'!B60<='Financial 40'!G15),'Financial 40'!O15, IF(AND('Data Validation'!C4='Financial 40'!G3,'Financial Statement'!B60>'Financial 40'!H16,'Financial Statement'!B60<='Financial 40'!G16),'Financial 40'!O16, IF(AND('Data Validation'!C4='Financial 40'!G3,'Financial Statement'!B60>'Financial 40'!H17),'Financial 40'!O17, IF(AND('Data Validation'!C4='Financial 40'!I3,'Financial Statement'!B60<='Financial 40'!J13),'Financial 40'!O13, IF(AND('Data Validation'!C4='Financial 40'!I3,'Financial Statement'!B60>'Financial 40'!J14,'Financial Statement'!B60<='Financial 40'!I14),'Financial 40'!O14, IF(AND('Data Validation'!C4='Financial 40'!I3,'Financial Statement'!B60>'Financial 40'!J15,'Financial Statement'!B60<='Financial 40'!I15),'Financial 40'!O15, IF(AND('Data Validation'!C4='Financial 40'!I3,'Financial Statement'!B60>'Financial 40'!J16,'Financial Statement'!B60<='Financial 40'!I16),'Financial 40'!O16, IF(AND('Data Validation'!C4='Financial 40'!I3,'Financial Statement'!B60>'Financial 40'!J17),'Financial 40'!O17, IF(AND('Data Validation'!C4='Financial 40'!K3,'Financial Statement'!B60<='Financial 40'!L13),'Financial 40'!O13, IF(AND('Data Validation'!C4='Financial 40'!K3,'Financial Statement'!B60>'Financial 40'!L14,'Financial Statement'!B60<='Financial 40'!K14),'Financial 40'!O14, IF(AND('Data Validation'!C4='Financial 40'!K3,'Financial Statement'!B60>'Financial 40'!L15,'Financial Statement'!B60<='Financial 40'!K15),'Financial 40'!O15, IF(AND('Data Validation'!C4='Financial 40'!K3,'Financial Statement'!B60>'Financial 40'!L16,'Financial Statement'!B60<='Financial 40'!K16),'Financial 40'!O16, IF(AND('Data Validation'!C4='Financial 40'!K3,'Financial Statement'!B60>'Financial 40'!L17),'Financial 40'!O17, IF(AND('Data Validation'!C4='Financial 40'!M3,'Financial Statement'!B60<='Financial 40'!N13),'Financial 40'!O13, IF(AND('Data Validation'!C4='Financial 40'!M3,'Financial Statement'!B60>'Financial 40'!N14,'Financial Statement'!B60<='Financial 40'!M14),'Financial 40'!O14, IF(AND('Data Validation'!C4='Financial 40'!M3,'Financial Statement'!B60>'Financial 40'!N15,'Financial Statement'!B60<='Financial 40'!M15),'Financial 40'!O15, IF(AND('Data Validation'!C4='Financial 40'!M3,'Financial Statement'!B60>'Financial 40'!N16,'Financial Statement'!B60<='Financial 40'!M16),'Financial 40'!O16, IF(AND('Data Validation'!C4='Financial 40'!M3,'Financial Statement'!B60>'Financial 40'!N17),'Financial 40'!O17))))))))))))))))))))))))))))))) -> 0.05
B8: Return on Asset =Net Income after tax /Total asset) | C8: ='Financial 40'!O19 -> 0.03 | D8: =IF(AND('Data Validation'!C4='Financial 40'!C3,'Financial Statement'!B66>='Financial 40'!D19),'Financial 40'!O19, IF(AND('Data Validation'!C4='Financial 40'!C3,'Financial Statement'!B66<'Financial 40'!D20,'Financial Statement'!B66>='Financial 40'!C20),'Financial 40'!O20, IF(AND('Data Validation'!C4='Financial 40'!C3,'Financial Statement'!B66<'Financial 40'!D21,'Financial Statement'!B66>='Financial 40'!C21),'Financial 40'!O21, IF(AND('Data Validation'!C4='Financial 40'!C3,'Financial Statement'!B66<'Financial 40'!D22,'Financial Statement'!B66>='Financial 40'!C22),'Financial 40'!O22, IF(AND('Data Validation'!C4='Financial 40'!C3,'Financial Statement'!B66<'Financial 40'!D23,'Financial Statement'!B66>='Financial 40'!C23),'Financial 40'!O23, IF(AND('Data Validation'!C4='Financial 40'!C3,'Financial Statement'!B66<'Financial 40'!D24),'Financial 40'!O24, IF(AND('Data Validation'!C4='Financial 40'!E3,'Financial Statement'!B66>='Financial 40'!F19),'Financial 40'!O19, IF(AND('Data Validation'!C4='Financial 40'!E3,'Financial Statement'!B66<'Financial 40'!F20,'Financial Statement'!B66>='Financial 40'!E20),'Financial 40'!O20, IF(AND('Data Validation'!C4='Financial 40'!E3,'Financial Statement'!B66<'Financial 40'!F21,'Financial Statement'!B66>='Financial 40'!E21),'Financial 40'!O21, IF(AND('Data Validation'!C4='Financial 40'!E3,'Financial Statement'!B66<'Financial 40'!F22,'Financial Statement'!B66>='Financial 40'!E22),'Financial 40'!O22, IF(AND('Data Validation'!C4='Financial 40'!E3,'Financial Statement'!B66<'Financial 40'!F23,'Financial Statement'!B66>='Financial 40'!E23),'Financial 40'!O23, IF(AND('Data Validation'!C4='Financial 40'!E3,'Financial Statement'!B66<'Financial 40'!F24),'Financial 40'!O24, IF(AND('Data Validation'!C4='Financial 40'!G3,'Financial Statement'!B66>='Financial 40'!H19),'Financial 40'!O19, IF(AND('Data Validation'!C4='Financial 40'!G3,'Financial Statement'!B66<'Financial 40'!H20,'Financial Statement'!B66>='Financial 40'!G20),'Financial 40'!O20, IF(AND('Data Validation'!C4='Financial 40'!G3,'Financial Statement'!B66<'Financial 40'!H21,'Financial Statement'!B66>='Financial 40'!G21),'Financial 40'!O21, IF(AND('Data Validation'!C4='Financial 40'!G3,'Financial Statement'!B66<'Financial 40'!H22,'Financial Statement'!B66>='Financial 40'!G22),'Financial 40'!O22, IF(AND('Data Validation'!C4='Financial 40'!G3,'Financial Statement'!B66<'Financial 40'!H23,'Financial Statement'!B66>='Financial 40'!G23),'Financial 40'!O23, IF(AND('Data Validation'!C4='Financial 40'!G3,'Financial Statement'!B66<'Financial 40'!H24),'Financial 40'!O24, IF(AND('Data Validation'!C4='Financial 40'!I3,'Financial Statement'!B66>='Financial 40'!J19),'Financial 40'!O19, IF(AND('Data Validation'!C4='Financial 40'!I3,'Financial Statement'!B66<'Financial 40'!J20,'Financial Statement'!B66>='Financial 40'!I20),'Financial 40'!O20, IF(AND('Data Validation'!C4='Financial 40'!I3,'Financial Statement'!B66<'Financial 40'!J21,'Financial Statement'!B66>='Financial 40'!I21),'Financial 40'!O21, IF(AND('Data Validation'!C4='Financial 40'!I3,'Financial Statement'!B66<'Financial 40'!J22,'Financial Statement'!B66>='Financial 40'!I22),'Financial 40'!O22, IF(AND('Data Validation'!C4='Financial 40'!I3,'Financial Statement'!B66<'Financial 40'!J23,'Financial Statement'!B66>='Financial 40'!I23),'Financial 40'!O23, IF(AND('Data Validation'!C4='Financial 40'!I3,'Financial Statement'!B66<'Financial 40'!J24),'Financial 40'!O24, IF(AND('Data Validation'!C4='Financial 40'!K3,'Financial Statement'!B66>='Financial 40'!L19),'Financial 40'!O19, IF(AND('Data Validation'!C4='Financial 40'!K3,'Financial Statement'!B66<'Financial 40'!L20,'Financial Statement'!B66>='Financial 40'!K20),'Financial 40'!O20, IF(AND('Data Validation'!C4='Financial 40'!K3,'Financial Statement'!B66<'Financial 40'!L21,'Financial Statement'!B66>='Financial 40'!K21),'Financial 40'!O21, IF(AND('Data Validation'!C4='Financial 40'!K3,'Financial Statement'!B66<'Financial 40'!L22,'Financial Statement'!B66>='Financial 40'!K22),'Financial 40'!O22, IF(AND('Data Validation'!C4='Financial 40'!K3,'Financial Statement'!B66<'Financial 40'!L23,'Financial Statement'!B66>='Financial 40'!K23),'Financial 40'!O23, IF(AND('Data Validation'!C4='Financial 40'!K3,'Financial Statement'!B66<'Financial 40'!L24),'Financial 40'!O24, IF(AND('Data Validation'!C4='Financial 40'!M3,'Financial Statement'!B66>='Financial 40'!N19),'Financial 40'!O19, IF(AND('Data Validation'!C4='Financial 40'!M3,'Financial Statement'!B66<'Financial 40'!N20,'Financial Statement'!B66>='Financial 40'!M20),'Financial 40'!O20, IF(AND('Data Validation'!C4='Financial 40'!M3,'Financial Statement'!B66<'Financial 40'!N21,'Financial Statement'!B66>='Financial 40'!M21),'Financial 40'!O21, IF(AND('Data Validation'!C4='Financial 40'!M3,'Financial Statement'!B66<'Financial 40'!N22,'Financial Statement'!B66>='Financial 40'!M22),'Financial 40'!O22, IF(AND('Data Validation'!C4='Financial 40'!M3,'Financial Statement'!B66<'Financial 40'!N23,'Financial Statement'!B66>='Financial 40'!M23),'Financial 40'!O23, IF(AND('Data Validation'!C4='Financial 40'!M3,'Financial Statement'!B66<'Financial 40'!N24),'Financial 40'!O24)))))))))))))))))))))))))))))))))))) -> #DIV/0!
B9: Operating profit Margin(Operating profit/Total Sales) | C9: ='Financial 40'!O25 -> 0.05 | D9: =IF(AND('Data Validation'!C4='Financial 40'!C3,'Financial Statement'!B69>='Financial 40'!D25),'Financial 40'!O25, IF(AND('Data Validation'!C4='Financial 40'!C3,'Financial Statement'!B69<'Financial 40'!D26,'Financial Statement'!B69>='Financial 40'!C26),'Financial 40'!O26, IF(AND('Data Validation'!C4='Financial 40'!C3,'Financial Statement'!B69<'Financial 40'!D27,'Financial Statement'!B69>='Financial 40'!C27),'Financial 40'!O27, IF(AND('Data Validation'!C4='Financial 40'!C3,'Financial Statement'!B69<'Financial 40'!D28,'Financial Statement'!B69>='Financial 40'!C28),'Financial 40'!O28, IF(AND('Data Validation'!C4='Financial 40'!C3,'Financial Statement'!B69<'Financial 40'!D29),'Financial 40'!O29, IF(AND('Data Validation'!C4='Financial 40'!E3,'Financial Statement'!B69>='Financial 40'!F25),'Financial 40'!O25, IF(AND('Data Validation'!C4='Financial 40'!E3,'Financial Statement'!B69<'Financial 40'!F26,'Financial Statement'!B69>='Financial 40'!E26),'Financial 40'!O26, IF(AND('Data Validation'!C4='Financial 40'!E3,'Financial Statement'!B69<'Financial 40'!F27,'Financial Statement'!B69>='Financial 40'!E27),'Financial 40'!O27, IF(AND('Data Validation'!C4='Financial 40'!E3,'Financial Statement'!B69<'Financial 40'!F28,'Financial Statement'!B69>='Financial 40'!E28),'Financial 40'!O28, IF(AND('Data Validation'!C4='Financial 40'!E3,'Financial Statement'!B69<'Financial 40'!F29),'Financial 40'!O29, IF(AND('Data Validation'!C4='Financial 40'!G3,'Financial Statement'!B69>='Financial 40'!H25),'Financial 40'!O25, IF(AND('Data Validation'!C4='Financial 40'!G3,'Financial Statement'!B69<'Financial 40'!H26,'Financial Statement'!B69>='Financial 40'!G26),'Financial 40'!O26, IF(AND('Data Validation'!C4='Financial 40'!G3,'Financial Statement'!B69<'Financial 40'!H27,'Financial Statement'!B69>='Financial 40'!G27),'Financial 40'!O27, IF(AND('Data Validation'!C4='Financial 40'!G3,'Financial Statement'!B69<'Financial 40'!H28,'Financial Statement'!B69>='Financial 40'!G28),'Financial 40'!O28, IF(AND('Data Validation'!C4='Financial 40'!G3,'Financial Statement'!B69<'Financial 40'!H29),'Financial 40'!O29, IF(AND('Data Validation'!C4='Financial 40'!I3,'Financial Statement'!B69>='Financial 40'!J25),'Financial 40'!O25, IF(AND('Data Validation'!C4='Financial 40'!I3,'Financial Statement'!B69<'Financial 40'!J26,'Financial Statement'!B69>='Financial 40'!I26),'Financial 40'!O26, IF(AND('Data Validation'!C4='Financial 40'!I3,'Financial Statement'!B69<'Financial 40'!J27,'Financial Statement'!B69>='Financial 40'!I27),'Financial 40'!O27, IF(AND('Data Validation'!C4='Financial 40'!I3,'Financial Statement'!B69<'Financial 40'!J28,'Financial Statement'!B69>='Financial 40'!I28),'Financial 40'!O28, IF(AND('Data Validation'!C4='Financial 40'!I3,'Financial Statement'!B69<'Financial 40'!J29),'Financial 40'!O29, IF(AND('Data Validation'!C4='Financial 40'!K3,'Financial Statement'!B69>='Financial 40'!L25),'Financial 40'!O25, IF(AND('Data Validation'!C4='Financial 40'!K3,'Financial Statement'!B69<'Financial 40'!L26,'Financial Statement'!B69>='Financial 40'!K26),'Financial 40'!O26, IF(AND('Data Validation'!C4='Financial 40'!K3,'Financial Statement'!B69<'Financial 40'!L27,'Financial Statement'!B69>='Financial 40'!K27),'Financial 40'!O27, IF(AND('Data Validation'!C4='Financial 40'!K3,'Financial Statement'!B69<'Financial 40'!L28,'Financial Statement'!B69>='Financial 40'!K28),'Financial 40'!O28, IF(AND('Data Validation'!C4='Financial 40'!K3,'Financial Statement'!B69<'Financial 40'!L29),'Financial 40'!O29, IF(AND('Data Validation'!C4='Financial 40'!M3,'Financial Statement'!B69>='Financial 40'!N25),'Financial 40'!O25, IF(AND('Data Validation'!C4='Financial 40'!M3,'Financial Statement'!B69<'Financial 40'!N26,'Financial Statement'!B69>='Financial 40'!M26),'Financial 40'!O26, IF(AND('Data Validation'!C4='Financial 40'!M3,'Financial Statement'!B69<'Financial 40'!N27,'Financial Statement'!B69>='Financial 40'!M27),'Financial 40'!O27, IF(AND('Data Validation'!C4='Financial 40'!M3,'Financial Statement'!B69<'Financial 40'!N28,'Financial Statement'!B69>='Financial 40'!M28),'Financial 40'!O28, IF(AND('Data Validation'!C4='Financial 40'!M3,'Financial Statement'!B69<'Financial 40'!N29),'Financial 40'!O29)))))))))))))))))))))))))))))) -> #DIV/0!
